Workbook

Sheet COMPOSICION FTE
B3: CARGO | C3: 10 | D3: 11 | E3: 5 | F3: 6 | G3: 10.4624 | H3: 11.4624 | I3: 5.2025 | J3: 8 | K3: 10.58 | L3: 7 | M3: 6.405 | N3: 7.2025 | O3: 8.2025 | P3: 9 | Q3: 2 | R3: 4 | S3: 5.45 | T3: 5.405 | U3: 6.4624 | V3: 8.405 | W3: 8.6649 | X3: 6.2025 | Y3: 5.6649 | Z3: 8.4624 | AA3: 9.2025 | AB3: 7.405 | AC3: 9.405 | AD3: 12 | AE3: 9.8674 | AF3: 9.6649 | AG3: 3 | AH3: 5.04 | AI3: 4.48 | AJ3: 6.16 | AK3: 5.6 | AL3: 3.36
A4: 1 | B4: LIDER | C4: 1 | D4: 1 | E4: 1 | F4: 1 | G4: 1 | H4: 1 | I4: 1 | J4: 1 | K4: 1 | L4: 1 | M4: 1 | N4: 1 | O4: 1 | P4: 1 | Q4: 1 | R4: 1 | S4: 1 | T4: 1 | U4: 1 | V4: 1 | W4: 1 | X4: 1 | Y4: 1 | Z4: 1 | AA4: 1 | AB4: 1 | AC4: 1 | AD4: 1 | AE4: 1 | AF4: 1 | AG4: 1 | AH4: 1 | AI4: 1 | AJ4: 1 | AK4: 1 | AL4: 1
A5: 1 | B5: JEFE DE SALA | C5: 2 | D5: 2 | E5: 2 | F5: 2 | G5: 2 | H5: 2 | I5: 2 | J5: 2 | K5: 2 | L5: 2 | M5: 2 | N5: 2 | O5: 2 | P5: 2 | Q5: 0 | R5: 1 | S5: 2 | T5: 2 | U5: 2 | V5: 2 | W5: 2 | X5: 2 | Y5: 2 | Z5: 2 | AA5: 2 | AB5: 2 | AC5: 2 | AD5: 2 | AE5: 1 | AF5: 2 | AG5: 2 | AH5: 1 | AI5: 1 | AJ5: 1 | AK5: 1 | AL5: 1
A6: 1 | B6: CAJERO | C6: 7 | D6: 8 | E6: 2 | F6: 3 | G6: 7 | H6: 8 | I6: 2 | J6: 5 | K6: 6 | L6: 4 | M6: 3 | N6: 4 | O6: 5 | P6: 6 | Q6: 1 | R6: 2 | S6: 2 | T6: 2 | U6: 3 | V6: 5 | W6: 5 | X6: 3 | Y6: 2 | Z6: 5 | AA6: 6 | AB6: 4 | AC6: 6 | AD6: 9 | AE6: 7 | AF6: 6 | AJ6: 0 | AK6: 0 | AL6: 0
A7: 0.45 | B7: CAJERP PT 20 | C7: 0 | D7: 0 | E7: 0 | F7: 0 | G7: 0.45 | H7: 0 | I7: 0.45 | J7: 0 | K7: 2 | L7: 0 | M7: 0.9 | N7: 0.45 | O7: 0.45 | P7: 0 | Q7: 0 | R7: 0 | S7: 0.45 | T7: 0.9 | U7: 0 | V7: 0.9 | W7: 0.45 | X7: 0.45 | Y7: 0.45 | Z7: 0 | AA7: 0.45 | AB7: 0.9 | AC7: 0.9 | AD7: 0 | AE7: 0.9 | AF7: 0.45 | AJ7: 0 | AK7: 0 | AL7: 0
A8: 0.68 | B8: CAJERO PT 30 | C8: 0 | D8: 0 | E8: 0 | F8: 0 | G8: 0 | H8: 0.68 | I8: 0 | J8: 0 | K8: 1 | L8: 0 | M8: 0 | N8: 0 | O8: 0 | P8: 0 | Q8: 0 | R8: 0 | S8: 0 | T8: 0 | U8: 0.68 | V8: 0 | W8: 0.68 | X8: 0 | Y8: 0.68 | Z8: 0.68 | AA8: 0 | AB8: 0 | AC8: 0 | AD8: 0 | AE8: 0.68 | AF8: 0.68 | AJ8: 0 | AK8: 0 | AL8: 2
A9: 0.56 | B9: CAJERO PT 25 | AH9: 3 | AI9: 2 | AJ9: 5 | AK9: 4 | AL9: 0
A10: 0.34 | B10: CAJERO PT 15 | AH10: 4 | AI10: 4 | AJ10: 4 | AK10: 4 | AL10: 0
B11: FTE AUTORIZADO | C11: =($A$4*C4)+($A$5*C5)+($A$6*C6)+($A$7*C7)+($A$8*C8)+($A$9*C9)+($A$10*C10) -> 10 | D11: =($A$4*D4)+($A$5*D5)+($A$6*D6)+($A$7*D7)+($A$8*D8)+($A$9*D9)+($A$10*D10) -> 11 | E11: =($A$4*E4)+($A$5*E5)+($A$6*E6)+($A$7*E7)+($A$8*E8)+($A$9*E9)+($A$10*E10) -> 5 | F11: =($A$4*F4)+($A$5*F5)+($A$6*F6)+($A$7*F7)+($A$8*F8)+($A$9*F9)+($A$10*F10) -> 6 | G11: =($A$4*G4)+($A$5*G5)+($A$6*G6)+($A$7*G7)+($A$8*G8)+($A$9*G9)+($A$10*G10) -> 10.2025 | H11: =($A$4*H4)+($A$5*H5)+($A$6*H6)+($A$7*H7)+($A$8*H8)+($A$9*H9)+($A$10*H10) -> 11.4624 | I11: =($A$4*I4)+($A$5*I5)+($A$6*I6)+($A$7*I7)+($A$8*I8)+($A$9*I9)+($A$10*I10) -> 5.2025 | J11: =($A$4*J4)+($A$5*J5)+($A$6*J6)+($A$7*J7)+($A$8*J8)+($A$9*J9)+($A$10*J10) -> 8 | ... AL11: =($A$4*AL4)+($A$5*AL5)+($A$6*AL6)+($A$7*AL7)+($A$8*AL8)+($A$9*AL9)+($A$10*AL10) -> 3.36 | AM11: =5.26-0.56 -> 4.7 | AN11: =AM11-AK11 -> -0.9
K13: 9.45
K14: =K13-K11 -> -1.13
C15: FTE AUTORIZADO | D15: LIDER | E15: JEFE DE SALA | F15: CAJERO | G15: CAJERO PT 30 | H15: PT25 | I15: CAJERP PT 20 | J15: PT15 | Q15: CAJERP PT 20 | S15: 0.45
C16: 10 | D16: 1 | E16: 2 | F16: 7 | G16: 0 | I16: 0 | Q16: CAJERO PT 30 | S16: 0.68
C17: 11 | D17: 1 | E17: 2 | F17: 8 | G17: 0 | I17: 0 | Q17: CAJERO PT 25 | S17: 0.56
C18: 5 | D18: 1 | E18: 2 | F18: 2 | G18: 0 | I18: 0 | Q18: CAJERO PT 15 | S18: 0.34
C19: 6 | D19: 1 | E19: 2 | F19: 3 | G19: 0 | I19: 0
C20: 10.68 | D20: 1 | E20: 2 | F20: 7 | G20: 0.68 | I20: 0
C21: 11.68 | D21: 1 | E21: 2 | F21: 8 | G21: 0.68 | I21: 0
C22: 5.45 | D22: 1 | E22: 2 | F22: 2 | G22: 0 | I22: 0.45
C23: 8 | D23: 1 | E23: 2 | F23: 5 | G23: 0 | I23: 0
C24: 7 | D24: 1 | E24: 2 | F24: 4 | G24: 0 | I24: 0
C25: 6.9 | D25: 1 | E25: 2 | F25: 3 | G25: 0 | I25: 0.9
C26: 7.45 | D26: 1 | E26: 2 | F26: 4 | G26: 0 | I26: 0.45
C27: 8.45 | D27: 1 | E27: 2 | F27: 5 | G27: 0 | I27: 0.45
C28: 9 | D28: 1 | E28: 2 | F28: 6 | G28: 0 | I28: 0
C29: 2 | D29: 1 | E29: 0 | F29: 1 | G29: 0 | I29: 0
C30: 4 | D30: 1 | E30: 1 | F30: 2 | G30: 0 | I30: 0
... C39: 9.45 | D39: 1 | E39: 2 | F39: 6 | G39: 0 | I39: 0.45
C40: 5.04 | D40: 1 | E40: 1 | F40: 0 | G40: 0 | H40: 3 | I40: 0 | J40: 4
C41: 6.28 | D41: 1 | E41: 1 | G41: 1 | H41: 4 | J41: 4
C42: 2.1 | D42: 1 | G42: 2

Sheet ABRIL_26
D3: REVISIÓN / ACTUALIZACIÓN
C6: 1 | D6: =C6+1 -> 2 | E6: =D6+1 -> 3 | F6: =E6+1 -> 4 | G6: 5 | H6: =G6+1 -> 6 | I6: =H6+1 -> 7 | J6: =I6+1 -> 8 | K6: =J6+1 -> 9 | L6: =K6+1 -> 10 | M6: =L6+1 -> 11 | N6: =M6+1 -> 12 | O6: =N6+1 -> 13 | ... T6: =S6+1 -> 18 | U6: 20 | W6: 1 | X6: 1 | Y6: 1 | Z6: =30/44 -> 0.68181818 | AA6: =25/44 -> 0.56818182 | AB6: =20/44 -> 0.45454545 | AC6: =15/44 -> 0.34090909
C7: CECO | D7: NOMBRE MAESTRA | E7: GEO | F7: FTE AUT | G7: ESTADO RH | H7: GENERACION | I7: JEFE OPERACIONES | J7: ASESOR TIENDA | K7: TIENDA ESTIVAL | L7: COMUNA | M7: REGION | N7: RECLUTADOR | O7: CECO | P7: JORNADA OPERACIÓN | Q7: PLAN RESCATE | R7: OBJETIVO VENTA | S7: MACROZONA | T7: TIENDA BATTING | U7: ONE TIME | V7: OBSERVACION | W7: LIDER | X7: JEFE DE SALA | Y7: CAJERO | Z7: CAJERO PT 30 | AA7: PT25 | AB7: CAJERP PT 20 | AC7: PT15 | AD7: FTE TOTAL
C8: 50OEM | D8: OKM CIUDAD EMPRESARIAL | E8: OKM CIUDAD EMPRESARIAL | F8: - | G8: CIERRE DEFINITIVO | H8: TMCB OKM | J8: 0 | L8: HUECHURABA | M8: METROPOLITANA | O8: 50OEM | P8: 12HRS | Q8: NO | S8: 0 | T8: NO | U8: NO | AD8: =SUMPRODUCT($W$6:$AC$6,W8:AC8) -> 0 | AE8: =VLOOKUP(C8,#REF!,1,0) -> #REF!
C9: 50BPT | D9: ECUADOR PURISIMA | E9: ECUADOR PURISIMA | F9: - | G9: CIERRE DEFINITIVO | H9: TMCB | J9: 0 | L9: ESTACIÓN CENTRAL | M9: METROPOLITANA | O9: 50BPT | P9: 12HRS | Q9: NO | S9: 0 | T9: NO | U9: NO | AD9: =SUMPRODUCT($W$6:$AC$6,W9:AC9) -> 0 | AE9: =VLOOKUP(C9,#REF!,1,0) -> #REF!
C10: 50ODA | D10: OKM DIEGO DE ALMAGRO | E10: OKM DIEGO DE ALMAGRO | F10: - | G10: CIERRE DEFINITIVO | H10: TMCB OKM | J10: RODRIGUEZ ABREU ROSA | L10: PROVIDENCIA | M10: METROPOLITANA | O10: 50ODA | P10: 12HRS | Q10: NO | S10: 0 | T10: NO | U10: NO | AD10: =SUMPRODUCT($W$6:$AC$6,W10:AC10) -> 0 | AE10: =VLOOKUP(C10,#REF!,1,0) -> #REF!
C11: 50ODP | D11: OKM DIEGO PORTALES | E11: OKM DIEGO PORTALES | F11: - | G11: CIERRE DEFINITIVO | H11: TMCB OKM | J11: 0 | L11: VIÑA DEL MAR | M11: VALPARAISO | O11: 50ODP | P11: 12HRS | Q11: NO | S11: 0 | T11: NO | U11: NO | AD11: =SUMPRODUCT($W$6:$AC$6,W11:AC11) -> 0 | AE11: =VLOOKUP(C11,#REF!,1,0) -> #REF!
C12: 50OMN | D12: OKM MORANDE | E12: OKM MORANDE | F12: - | G12: CIERRE DEFINITIVO | H12: TMCB OKM | J12: LOPEZ CALDERON LUIS GERARDO | L12: SANTIAGO | M12: METROPOLITANA | O12: 50OMN | P12: 12HRS | Q12: NO | S12: 0 | T12: NO | U12: NO | AD12: =SUMPRODUCT($W$6:$AC$6,W12:AC12) -> 0 | AE12: =VLOOKUP(C12,#REF!,1,0) -> #REF!
C13: 50OSB | D13: SIMON BOLIVAR 2 | E13: OKM SIMÓN BOLIVAR | F13: - | G13: CIERRE DEFINITIVO | H13: TMCB OKM | J13: GAMERRE URZUA CECILIA | L13: ÑUÑOA | M13: METROPOLITANA | O13: 50OSB | P13: 12HRS | Q13: NO | S13: 0 | T13: NO | U13: NO | AD13: =SUMPRODUCT($W$6:$AC$6,W13:AC13) -> 0 | AE13: =VLOOKUP(C13,#REF!,1,0) -> #REF!
C14: 50OTO | D14: OKM TOESCA | E14: OKM TOESCA | F14: - | G14: CIERRE DEFINITIVO | H14: TMCB OKM | J14: RIQUELME ESTAY ROBERTO | L14: SANTIAGO | M14: METROPOLITANA | O14: 50OTO | P14: 12HRS | Q14: NO | S14: 0 | T14: NO | U14: NO | AD14: =SUMPRODUCT($W$6:$AC$6,W14:AC14) -> 0 | AE14: =VLOOKUP(C14,#REF!,1,0) -> #REF!
C15: 50OHT | D15: HAMBURGO 2 | E15: OKM HAMBURGO | F15: - | G15: CIERRE DEFINITIVO | H15: TMCB OKM | J15: LOPEZ CALDERON LUIS GERARDO | L15: ÑUÑOA | M15: METROPOLITANA | O15: 50OHT | P15: 12HRS | Q15: NO | S15: 0 | T15: NO | U15: NO | AD15: =SUMPRODUCT($W$6:$AC$6,W15:AC15) -> 0 | AE15: =VLOOKUP(C15,#REF!,1,0) -> #REF!
C16: 50OMP | D16: OKM MALL PLAZA OESTE | E16: OKM MALL PLAZA OESTE | F16: 0 | G16: CIERRE DEFINITIVO | H16: TMCB | J16: PINERUA JAIMES JESUS | L16: CERRILLOS | M16: METROPOLITANA | O16: 50OMP | P16: 12HRS | Q16: NO | S16: 0 | T16: NO | U16: NO | AD16: =SUMPRODUCT($W$6:$AC$6,W16:AC16) -> 0 | AE16: =VLOOKUP(C16,#REF!,1,0) -> #REF!
C17: 50OPR | D17: AVENIDA PERU | E17: OKM AVENIDA PERÚ | F17: - | G17: CIERRE DEFINITIVO | H17: TMCB OKM | J17: 0 | L17: RECOLETA | M17: METROPOLITANA | O17: 50OPR | P17: 12HRS | Q17: NO | S17: 0 | T17: NO | U17: NO | AD17: =SUMPRODUCT($W$6:$AC$6,W17:AC17) -> 0 | AE17: =VLOOKUP(C17,#REF!,1,0) -> #REF!
C18: 50AMU | D18: TORRE AMUNATEGUI | E18: TORRE AMUNATEGUI | F18: - | G18: CIERRE DEFINITIVO | H18: TNM | J18: 0 | L18: SANTIAGO | M18: METROPOLITANA | O18: 50AMU | P18: 12HRS | Q18: NO | S18: 0 | T18: NO | U18: NO | AD18: =SUMPRODUCT($W$6:$AC$6,W18:AC18) -> 0 | AE18: =VLOOKUP(C18,#REF!,1,0) -> #REF!
C19: 500LI | D19: JJ PEREZ | E19: JJ PEREZ | F19: - | G19: CIERRE DEFINITIVO | H19: TNM | J19: ESCOBAR VALDES VALESKA SOLEDAD | L19: CALERA | M19: VALPARAISO | O19: 500LI | P19: 12HRS | Q19: NO | S19: 0 | T19: NO | U19: NO | AD19: =SUMPRODUCT($W$6:$AC$6,W19:AC19) -> 0 | AE19: =VLOOKUP(C19,#REF!,1,0) -> #REF!
C20: 500UN | D20: PLAZA CHIGUAYANTE | E20: PLAZA CHIGUAYANTE | F20: - | G20: CIERRE DEFINITIVO | H20: T2024 | J20: ZAMBRANO JARA CAROLINA GRACIELA | L20: CHIGUAYANTE | M20: BIOBIO | O20: 500UN | P20: 12HRS | Q20: NO | S20: 0 | T20: NO | U20: NO | AD20: =SUMPRODUCT($W$6:$AC$6,W20:AC20) -> 0 | AE20: =VLOOKUP(C20,#REF!,1,0) -> #REF!
C21: 501CG | D21: IRARRAZAVAL 1 | E21: IRARRAZAVAL 1 | F21: - | G21: CIERRE DEFINITIVO | H21: TNM | J21: RUIZ FERRER VANNA | L21: ÑUÑOA | M21: METROPOLITANA | O21: 501CG | P21: 12HRS | Q21: NO | S21: 0 | T21: NO | U21: NO | AD21: =SUMPRODUCT($W$6:$AC$6,W21:AC21) -> 0 | AE21: =VLOOKUP(C21,#REF!,1,0) -> #REF!
C22: 502IY | D22: INDEPENDENCIA 2 | E22: INDEPENDENCIA 2 | F22: - | G22: CIERRE DEFINITIVO | H22: TNM | J22: 0 | L22: INDEPENDENCIA | M22: METROPOLITANA | O22: 502IY | P22: 12HRS | Q22: NO | S22: 0 | T22: NO | U22: NO | AD22: =SUMPRODUCT($W$6:$AC$6,W22:AC22) -> 0 | AE22: =VLOOKUP(C22,#REF!,1,0) -> #REF!
C23: 502UE | D23: MIRAFLORES | E23: MIRAFLORES | F23: - | G23: CIERRE DEFINITIVO | H23: TNM | J23: BENITEZ QUILODRAN HUGO | L23: SANTIAGO | M23: METROPOLITANA | O23: 502UE | P23: 12HRS | Q23: NO | S23: 0 | T23: NO | U23: NO | AD23: =SUMPRODUCT($W$6:$AC$6,W23:AC23) -> 0 | AE23: =VLOOKUP(C23,#REF!,1,0) -> #REF!
C24: 503LC | D24: TALCA 2 | E24: TALCA 2 | F24: - | G24: CIERRE DEFINITIVO | H24: TNM | J24: PINERUA JAIMES JESUS | L24: TALCA | M24: MAULE | O24: 503LC | P24: 12HRS | Q24: NO | S24: 0 | T24: NO | U24: NO | AD24: =SUMPRODUCT($W$6:$AC$6,W24:AC24) -> 0 | AE24: =VLOOKUP(C24,#REF!,1,0) -> #REF!
C25: 503YO | D25: SAN DIEGO 2 | E25: SAN DIEGO 2 | F25: - | G25: CIERRE DEFINITIVO | H25: TNM | J25: BENITEZ QUILODRAN HUGO | L25: SANTIAGO | M25: METROPOLITANA | O25: 503YO | P25: 12HRS | Q25: NO | S25: 0 | T25: NO | U25: NO | AD25: =SUMPRODUCT($W$6:$AC$6,W25:AC25) -> 0 | AE25: =VLOOKUP(C25,#REF!,1,0) -> #REF!
C26: 504GZ | D26: OHIGGINS ANGOL | E26: OHIGGINS ANGOL | F26: - | G26: CIERRE DEFINITIVO | H26: TNM | J26: ZAMBRANO JARA CAROLINA GRACIELA | L26: CONCEPCIÓN | M26: BIOBIO | O26: 504GZ | P26: 12HRS | Q26: NO | S26: 0 | T26: NO | U26: NO | AD26: =SUMPRODUCT($W$6:$AC$6,W26:AC26) -> 0 | AE26: =VLOOKUP(C26,#REF!,1,0) -> #REF!
C27: 504UJ | D27: BANDERA 2 | E27: BANDERA 2 | F27: - | G27: CIERRE DEFINITIVO | H27: TNM | J27: LOPEZ CALDERON LUIS GERARDO | L27: SANTIAGO | M27: METROPOLITANA | O27: 504UJ | P27: 12HRS | Q27: NO | S27: 0 | T27: NO | U27: NO | AD27: =SUMPRODUCT($W$6:$AC$6,W27:AC27) -> 0 | AE27: =VLOOKUP(C27,#REF!,1,0) -> #REF!
C28: 5050J | D28: MALL PATIO RANCAGUA | E28: PATIO RANCAGUA | F28: - | G28: CIERRE DEFINITIVO | H28: TNM | J28: PINERUA JAIMES JESUS | L28: RANCAGUA | M28: BERNARDO OHIGGINS | O28: 5050J | P28: 12HRS | Q28: NO | S28: 0 | T28: NO | U28: NO | AD28: =SUMPRODUCT($W$6:$AC$6,W28:AC28) -> 0 | AE28: =VLOOKUP(C28,#REF!,1,0) -> #REF!
C29: 506J6 | D29: ABATE MOLINA | E29: ABATE MOLINA | F29: - | G29: CIERRE DEFINITIVO | H29: TNM | J29: 0 | L29: SANTIAGO | M29: METROPOLITANA | O29: 506J6 | P29: 12HRS | Q29: NO | S29: 0 | T29: NO | U29: NO | AD29: =SUMPRODUCT($W$6:$AC$6,W29:AC29) -> 0 | AE29: =VLOOKUP(C29,#REF!,1,0) -> #REF!
C30: 506ZY | D30: PEDRO TORRES | E30: PEDRO TORRES | F30: - | G30: CIERRE DEFINITIVO | H30: TNM | J30: GAMERRE URZUA CECILIA | L30: ÑUÑOA | M30: METROPOLITANA | O30: 506ZY | P30: 12HRS | Q30: NO | S30: 0 | T30: NO | U30: NO | AD30: =SUMPRODUCT($W$6:$AC$6,W30:AC30) -> 0 | AE30: =VLOOKUP(C30,#REF!,1,0) -> #REF!
C31: 508NJ | D31: LINARES | E31: LINARES 1 | F31: - | G31: CIERRE DEFINITIVO | H31: TNM | J31: PINERUA JAIMES JESUS | L31: LINARES | M31: MAULE | O31: 508NJ | P31: 12HRS | Q31: NO | S31: 0 | T31: NO | U31: NO | AD31: =SUMPRODUCT($W$6:$AC$6,W31:AC31) -> 0 | AE31: =VLOOKUP(C31,#REF!,1,0) -> #REF!
C32: 5091B | D32: HOLANDA 3 | E32: HOLANDA 3 | F32: - | G32: CIERRE DEFINITIVO | H32: TNM | J32: 0 | L32: PROVIDENCIA | M32: METROPOLITANA | O32: 5091B | P32: 12HRS | Q32: NO | S32: 0 | T32: NO | U32: NO | AD32: =SUMPRODUCT($W$6:$AC$6,W32:AC32) -> 0 | AE32: =VLOOKUP(C32,#REF!,1,0) -> #REF!
C33: 509H6 | D33: MACHALI SEWEL | E33: MACHALÍ SEWEL | F33: - | G33: CIERRE DEFINITIVO | H33: TNM | J33: PINERUA JAIMES JESUS | L33: MACHALÍ | M33: BERNARDO OHIGGINS | O33: 509H6 | P33: 12HRS | Q33: NO | S33: 0 | T33: NO | U33: NO | AD33: =SUMPRODUCT($W$6:$AC$6,W33:AC33) -> 0 | AE33: =VLOOKUP(C33,#REF!,1,0) -> #REF!
C34: 50AFU | D34: SANTA AMALIA | E34: SANTA AMALIA | F34: - | G34: CIERRE DEFINITIVO | H34: TNM | J34: ARAYA BURGOS ARIEL | L34: LA FLORIDA | M34: METROPOLITANA | O34: 50AFU | P34: 12HRS | Q34: NO | S34: 0 | T34: NO | U34: NO | AD34: =SUMPRODUCT($W$6:$AC$6,W34:AC34) -> 0 | AE34: =VLOOKUP(C34,#REF!,1,0) -> #REF!
C35: 50AGU | D35: EL AGUILUCHO | E35: EL AGUILUCHO | F35: - | G35: CIERRE DEFINITIVO | H35: TNM | J35: ARAYA BURGOS ARIEL | L35: PROVIDENCIA | M35: METROPOLITANA | O35: 50AGU | P35: 12HRS | Q35: NO | S35: 0 | T35: NO | U35: NO | AD35: =SUMPRODUCT($W$6:$AC$6,W35:AC35) -> 0 | AE35: =VLOOKUP(C35,#REF!,1,0) -> #REF!
C36: 50AJL | D36: LA CASTELLANA | E36: LA CASTELLANA | F36: - | G36: CIERRE DEFINITIVO | H36: T2024 | J36: LOPEZ CALDERON LUIS GERARDO | L36: LAS CONDES | M36: METROPOLITANA | O36: 50AJL | P36: 12HRS | Q36: NO | S36: 0 | T36: NO | U36: NO | AD36: =SUMPRODUCT($W$6:$AC$6,W36:AC36) -> 0 | AE36: =VLOOKUP(C36,#REF!,1,0) -> #REF!
C37: 50AL4 | D37: ANIBAL PINTO | E37: ANIBAL PINTO | F37: - | G37: CIERRE DEFINITIVO | H37: T2024 | J37: ZAMBRANO JARA CAROLINA GRACIELA | L37: CONCEPCIÓN | M37: BIOBIO | O37: 50AL4 | P37: 12HRS | Q37: NO | S37: 0 | T37: NO | U37: NO | AD37: =SUMPRODUCT($W$6:$AC$6,W37:AC37) -> 0 | AE37: =VLOOKUP(C37,#REF!,1,0) -> #REF!
C38: 50AZF | D38: PUDAHUEL SAN PABLO 2 | E38: PUDAHUEL SAN PABLO 2 | F38: - | G38: CIERRE DEFINITIVO | H38: TNM | J38: 0 | L38: PUDAHUEL | M38: METROPOLITANA | O38: 50AZF | P38: 12HRS | Q38: NO | S38: 0 | T38: NO | U38: NO | AD38: =SUMPRODUCT($W$6:$AC$6,W38:AC38) -> 0 | AE38: =VLOOKUP(C38,#REF!,1,0) -> #REF!
C39: 50BER | D39: EL BERGANTIN | E39: EL BERGANTIN | F39: - | G39: CIERRE DEFINITIVO | H39: TMCB | J39: LIAZ MONTERO GABRIEL | L39: LAS CONDES | M39: METROPOLITANA | O39: 50BER | P39: 12HRS | Q39: NO | S39: 0 | T39: NO | U39: NO | AD39: =SUMPRODUCT($W$6:$AC$6,W39:AC39) -> 0 | AE39: =VLOOKUP(C39,#REF!,1,0) -> #REF!
C40: 50BLL | D40: BILBAO LOS LEONES | E40: BILBAO LOS LEONES | F40: - | G40: CIERRE DEFINITIVO | H40: TMCB | J40: RODRIGUEZ ABREU ROSA | L40: PROVIDENCIA | M40: METROPOLITANA | O40: 50BLL | P40: 12HRS | Q40: NO | S40: 0 | T40: NO | U40: NO | AD40: =SUMPRODUCT($W$6:$AC$6,W40:AC40) -> 0 | AE40: =VLOOKUP(C40,#REF!,1,0) -> #REF!
C41: 50BMP | D41: SANTO DOMINGO | E41: SANTO DOMINGO | F41: - | G41: CIERRE DEFINITIVO | H41: TNM | J41: BENITEZ QUILODRAN HUGO | L41: SANTIAGO | M41: METROPOLITANA | O41: 50BMP | P41: 12HRS | Q41: NO | S41: 0 | T41: NO | U41: NO | AD41: =SUMPRODUCT($W$6:$AC$6,W41:AC41) -> 0 | AE41: =VLOOKUP(C41,#REF!,1,0) -> #REF!
C42: 50CEI | D42: BARCELONA | E42: BARCELONA | F42: - | G42: CIERRE DEFINITIVO | H42: T2024 | J42: ARAYA BURGOS ARIEL | L42: LA FLORIDA | M42: METROPOLITANA | O42: 50CEI | P42: 12HRS | Q42: NO | S42: 0 | T42: NO | U42: NO | AD42: =SUMPRODUCT($W$6:$AC$6,W42:AC42) -> 0 | AE42: =VLOOKUP(C42,#REF!,1,0) -> #REF!
C43: 50DBW | D43: RENACA 1 | E43: REÑACA 1 | F43: - | G43: CIERRE DEFINITIVO | H43: TNM | J43: ESCOBAR VALDES VALESKA SOLEDAD | L43: VIÑA DEL MAR | M43: VALPARAISO | O43: 50DBW | P43: 12HRS | Q43: NO | S43: 0 | T43: NO | U43: NO | AD43: =SUMPRODUCT($W$6:$AC$6,W43:AC43) -> 0 | AE43: =VLOOKUP(C43,#REF!,1,0) -> #REF!
C44: 50DXJ | D44: PROVIDENCIA 1 | E44: PROVIDENCIA 1 | F44: - | G44: CIERRE DEFINITIVO | H44: TMCB | J44: 0 | L44: PROVIDENCIA | M44: METROPOLITANA | O44: 50DXJ | P44: 12HRS | Q44: NO | S44: 0 | T44: NO | U44: NO | AD44: =SUMPRODUCT($W$6:$AC$6,W44:AC44) -> 0 | AE44: =VLOOKUP(C44,#REF!,1,0) -> #REF!
...

Sheet MARZO_26 
C6: 1 | D6: =C6+1 -> 2 | E6: =D6+1 -> 3 | F6: =E6+1 -> 4 | G6: 5 | H6: =G6+1 -> 6 | I6: =H6+1 -> 7 | J6: =I6+1 -> 8 | K6: =J6+1 -> 9 | L6: =K6+1 -> 10 | M6: =L6+1 -> 11 | N6: =M6+1 -> 12 | O6: =N6+1 -> 13 | ... T6: =S6+1 -> 18 | U6: 20 | W6: 1 | X6: 1 | Y6: 1 | Z6: =30/44 -> 0.68181818 | AA6: =25/44 -> 0.56818182 | AB6: =20/44 -> 0.45454545 | AC6: =15/44 -> 0.34090909
C7: CECO | D7: NOMBRE MAESTRA | E7: GEO | F7: FTE AUT | G7: ESTADO RH | H7: GENERACION | I7: JEFE OPERACIONES | J7: ASESOR TIENDA | K7: TIENDA ESTIVAL | L7: COMUNA | M7: REGION | N7: RECLUTADOR | O7: CECO | P7: JORNADA OPERACIÓN | Q7: PLAN RESCATE | R7: OBJETIVO VENTA | S7: MACROZONA | T7: TIENDA BATTING | U7: ONE TIME | V7: OBSERVACION | W7: LIDER | X7: JEFE DE SALA | Y7: CAJERO | Z7: CAJERO PT 30 | AA7: PT25 | AB7: CAJERP PT 20 | AC7: PT15 | AD7: FTE TOTAL
C8: 50OEM | D8: OKM CIUDAD EMPRESARIAL | E8: OKM CIUDAD EMPRESARIAL | F8: - | G8: CIERRE DEFINITIVO | H8: TMCB OKM | J8: 0 | L8: HUECHURABA | M8: METROPOLITANA | O8: 50OEM | P8: 12HRS | Q8: NO | S8: 0 | T8: NO | U8: NO | AD8: =SUMPRODUCT($W$6:$AC$6,W8:AC8) -> 0 | AE8: =VLOOKUP(C8,#REF!,1,0) -> #REF!
C9: 50BPT | D9: ECUADOR PURISIMA | E9: ECUADOR PURISIMA | F9: - | G9: CIERRE DEFINITIVO | H9: TMCB | J9: 0 | L9: ESTACIÓN CENTRAL | M9: METROPOLITANA | O9: 50BPT | P9: 12HRS | Q9: NO | S9: 0 | T9: NO | U9: NO | AD9: =SUMPRODUCT($W$6:$AC$6,W9:AC9) -> 0 | AE9: =VLOOKUP(C9,#REF!,1,0) -> #REF!
C10: 50ODA | D10: OKM DIEGO DE ALMAGRO | E10: OKM DIEGO DE ALMAGRO | F10: - | G10: CIERRE DEFINITIVO | H10: TMCB OKM | J10: RODRIGUEZ ABREU ROSA | L10: PROVIDENCIA | M10: METROPOLITANA | O10: 50ODA | P10: 12HRS | Q10: NO | S10: 0 | T10: NO | U10: NO | AD10: =SUMPRODUCT($W$6:$AC$6,W10:AC10) -> 0 | AE10: =VLOOKUP(C10,#REF!,1,0) -> #REF!
C11: 50ODP | D11: OKM DIEGO PORTALES | E11: OKM DIEGO PORTALES | F11: - | G11: CIERRE DEFINITIVO | H11: TMCB OKM | J11: 0 | L11: VIÑA DEL MAR | M11: VALPARAISO | O11: 50ODP | P11: 12HRS | Q11: NO | S11: 0 | T11: NO | U11: NO | AD11: =SUMPRODUCT($W$6:$AC$6,W11:AC11) -> 0 | AE11: =VLOOKUP(C11,#REF!,1,0) -> #REF!
C12: 50OMN | D12: OKM MORANDE | E12: OKM MORANDE | F12: - | G12: CIERRE DEFINITIVO | H12: TMCB OKM | J12: LOPEZ CALDERON LUIS GERARDO | L12: SANTIAGO | M12: METROPOLITANA | O12: 50OMN | P12: 12HRS | Q12: NO | S12: 0 | T12: NO | U12: NO | AD12: =SUMPRODUCT($W$6:$AC$6,W12:AC12) -> 0 | AE12: =VLOOKUP(C12,#REF!,1,0) -> #REF!
C13: 50OSB | D13: SIMON BOLIVAR 2 | E13: OKM SIMÓN BOLIVAR | F13: - | G13: CIERRE DEFINITIVO | H13: TMCB OKM | J13: GAMERRE URZUA CECILIA | L13: ÑUÑOA | M13: METROPOLITANA | O13: 50OSB | P13: 12HRS | Q13: NO | S13: 0 | T13: NO | U13: NO | AD13: =SUMPRODUCT($W$6:$AC$6,W13:AC13) -> 0 | AE13: =VLOOKUP(C13,#REF!,1,0) -> #REF!
C14: 50OTO | D14: OKM TOESCA | E14: OKM TOESCA | F14: - | G14: CIERRE DEFINITIVO | H14: TMCB OKM | J14: RIQUELME ESTAY ROBERTO | L14: SANTIAGO | M14: METROPOLITANA | O14: 50OTO | P14: 12HRS | Q14: NO | S14: 0 | T14: NO | U14: NO | AD14: =SUMPRODUCT($W$6:$AC$6,W14:AC14) -> 0 | AE14: =VLOOKUP(C14,#REF!,1,0) -> #REF!
C15: 50OHT | D15: HAMBURGO 2 | E15: OKM HAMBURGO | F15: - | G15: CIERRE DEFINITIVO | H15: TMCB OKM | J15: LOPEZ CALDERON LUIS GERARDO | L15: ÑUÑOA | M15: METROPOLITANA | O15: 50OHT | P15: 12HRS | Q15: NO | S15: 0 | T15: NO | U15: NO | AD15: =SUMPRODUCT($W$6:$AC$6,W15:AC15) -> 0 | AE15: =VLOOKUP(C15,#REF!,1,0) -> #REF!
C16: 50OMP | D16: OKM MALL PLAZA OESTE | E16: OKM MALL PLAZA OESTE | F16: 0 | G16: CIERRE DEFINITIVO | H16: TMCB | J16: PINERUA JAIMES JESUS | L16: CERRILLOS | M16: METROPOLITANA | O16: 50OMP | P16: 12HRS | Q16: NO | S16: 0 | T16: NO | U16: NO | AD16: =SUMPRODUCT($W$6:$AC$6,W16:AC16) -> 0 | AE16: =VLOOKUP(C16,#REF!,1,0) -> #REF!
C17: 50OPR | D17: AVENIDA PERU | E17: OKM AVENIDA PERÚ | F17: - | G17: CIERRE DEFINITIVO | H17: TMCB OKM | J17: 0 | L17: RECOLETA | M17: METROPOLITANA | O17: 50OPR | P17: 12HRS | Q17: NO | S17: 0 | T17: NO | U17: NO | AD17: =SUMPRODUCT($W$6:$AC$6,W17:AC17) -> 0 | AE17: =VLOOKUP(C17,#REF!,1,0) -> #REF!
C18: 50AMU | D18: TORRE AMUNATEGUI | E18: TORRE AMUNATEGUI | F18: - | G18: CIERRE DEFINITIVO | H18: TNM | J18: 0 | L18: SANTIAGO | M18: METROPOLITANA | O18: 50AMU | P18: 12HRS | Q18: NO | S18: 0 | T18: NO | U18: NO | AD18: =SUMPRODUCT($W$6:$AC$6,W18:AC18) -> 0 | AE18: =VLOOKUP(C18,#REF!,1,0) -> #REF!
C19: 500LI | D19: JJ PEREZ | E19: JJ PEREZ | F19: - | G19: CIERRE DEFINITIVO | H19: TNM | J19: ESCOBAR VALDES VALESKA SOLEDAD | L19: CALERA | M19: VALPARAISO | O19: 500LI | P19: 12HRS | Q19: NO | S19: 0 | T19: NO | U19: NO | AD19: =SUMPRODUCT($W$6:$AC$6,W19:AC19) -> 0 | AE19: =VLOOKUP(C19,#REF!,1,0) -> #REF!
C20: 500UN | D20: PLAZA CHIGUAYANTE | E20: PLAZA CHIGUAYANTE | F20: - | G20: CIERRE DEFINITIVO | H20: T2024 | J20: ZAMBRANO JARA CAROLINA GRACIELA | L20: CHIGUAYANTE | M20: BIOBIO | O20: 500UN | P20: 12HRS | Q20: NO | S20: 0 | T20: NO | U20: NO | AD20: =SUMPRODUCT($W$6:$AC$6,W20:AC20) -> 0 | AE20: =VLOOKUP(C20,#REF!,1,0) -> #REF!
C21: 501CG | D21: IRARRAZAVAL 1 | E21: IRARRAZAVAL 1 | F21: - | G21: CIERRE DEFINITIVO | H21: TNM | J21: RUIZ FERRER VANNA | L21: ÑUÑOA | M21: METROPOLITANA | O21: 501CG | P21: 12HRS | Q21: NO | S21: 0 | T21: NO | U21: NO | AD21: =SUMPRODUCT($W$6:$AC$6,W21:AC21) -> 0 | AE21: =VLOOKUP(C21,#REF!,1,0) -> #REF!
C22: 502IY | D22: INDEPENDENCIA 2 | E22: INDEPENDENCIA 2 | F22: - | G22: CIERRE DEFINITIVO | H22: TNM | J22: 0 | L22: INDEPENDENCIA | M22: METROPOLITANA | O22: 502IY | P22: 12HRS | Q22: NO | S22: 0 | T22: NO | U22: NO | AD22: =SUMPRODUCT($W$6:$AC$6,W22:AC22) -> 0 | AE22: =VLOOKUP(C22,#REF!,1,0) -> #REF!
C23: 502UE | D23: MIRAFLORES | E23: MIRAFLORES | F23: - | G23: CIERRE DEFINITIVO | H23: TNM | J23: BENITEZ QUILODRAN HUGO | L23: SANTIAGO | M23: METROPOLITANA | O23: 502UE | P23: 12HRS | Q23: NO | S23: 0 | T23: NO | U23: NO | AD23: =SUMPRODUCT($W$6:$AC$6,W23:AC23) -> 0 | AE23: =VLOOKUP(C23,#REF!,1,0) -> #REF!
C24: 503LC | D24: TALCA 2 | E24: TALCA 2 | F24: - | G24: CIERRE DEFINITIVO | H24: TNM | J24: PINERUA JAIMES JESUS | L24: TALCA | M24: MAULE | O24: 503LC | P24: 12HRS | Q24: NO | S24: 0 | T24: NO | U24: NO | AD24: =SUMPRODUCT($W$6:$AC$6,W24:AC24) -> 0 | AE24: =VLOOKUP(C24,#REF!,1,0) -> #REF!
C25: 503YO | D25: SAN DIEGO 2 | E25: SAN DIEGO 2 | F25: - | G25: CIERRE DEFINITIVO | H25: TNM | J25: BENITEZ QUILODRAN HUGO | L25: SANTIAGO | M25: METROPOLITANA | O25: 503YO | P25: 12HRS | Q25: NO | S25: 0 | T25: NO | U25: NO | AD25: =SUMPRODUCT($W$6:$AC$6,W25:AC25) -> 0 | AE25: =VLOOKUP(C25,#REF!,1,0) -> #REF!
C26: 504GZ | D26: OHIGGINS ANGOL | E26: OHIGGINS ANGOL | F26: - | G26: CIERRE DEFINITIVO | H26: TNM | J26: ZAMBRANO JARA CAROLINA GRACIELA | L26: CONCEPCIÓN | M26: BIOBIO | O26: 504GZ | P26: 12HRS | Q26: NO | S26: 0 | T26: NO | U26: NO | AD26: =SUMPRODUCT($W$6:$AC$6,W26:AC26) -> 0 | AE26: =VLOOKUP(C26,#REF!,1,0) -> #REF!
C27: 504UJ | D27: BANDERA 2 | E27: BANDERA 2 | F27: - | G27: CIERRE DEFINITIVO | H27: TNM | J27: LOPEZ CALDERON LUIS GERARDO | L27: SANTIAGO | M27: METROPOLITANA | O27: 504UJ | P27: 12HRS | Q27: NO | S27: 0 | T27: NO | U27: NO | AD27: =SUMPRODUCT($W$6:$AC$6,W27:AC27) -> 0 | AE27: =VLOOKUP(C27,#REF!,1,0) -> #REF!
C28: 5050J | D28: MALL PATIO RANCAGUA | E28: PATIO RANCAGUA | F28: - | G28: CIERRE DEFINITIVO | H28: TNM | J28: PINERUA JAIMES JESUS | L28: RANCAGUA | M28: BERNARDO OHIGGINS | O28: 5050J | P28: 12HRS | Q28: NO | S28: 0 | T28: NO | U28: NO | AD28: =SUMPRODUCT($W$6:$AC$6,W28:AC28) -> 0 | AE28: =VLOOKUP(C28,#REF!,1,0) -> #REF!
C29: 506J6 | D29: ABATE MOLINA | E29: ABATE MOLINA | F29: - | G29: CIERRE DEFINITIVO | H29: TNM | J29: 0 | L29: SANTIAGO | M29: METROPOLITANA | O29: 506J6 | P29: 12HRS | Q29: NO | S29: 0 | T29: NO | U29: NO | AD29: =SUMPRODUCT($W$6:$AC$6,W29:AC29) -> 0 | AE29: =VLOOKUP(C29,#REF!,1,0) -> #REF!
C30: 506ZY | D30: PEDRO TORRES | E30: PEDRO TORRES | F30: - | G30: CIERRE DEFINITIVO | H30: TNM | J30: GAMERRE URZUA CECILIA | L30: ÑUÑOA | M30: METROPOLITANA | O30: 506ZY | P30: 12HRS | Q30: NO | S30: 0 | T30: NO | U30: NO | AD30: =SUMPRODUCT($W$6:$AC$6,W30:AC30) -> 0 | AE30: =VLOOKUP(C30,#REF!,1,0) -> #REF!
C31: 508NJ | D31: LINARES | E31: LINARES 1 | F31: - | G31: CIERRE DEFINITIVO | H31: TNM | J31: PINERUA JAIMES JESUS | L31: LINARES | M31: MAULE | O31: 508NJ | P31: 12HRS | Q31: NO | S31: 0 | T31: NO | U31: NO | AD31: =SUMPRODUCT($W$6:$AC$6,W31:AC31) -> 0 | AE31: =VLOOKUP(C31,#REF!,1,0) -> #REF!
C32: 5091B | D32: HOLANDA 3 | E32: HOLANDA 3 | F32: - | G32: CIERRE DEFINITIVO | H32: TNM | J32: 0 | L32: PROVIDENCIA | M32: METROPOLITANA | O32: 5091B | P32: 12HRS | Q32: NO | S32: 0 | T32: NO | U32: NO | AD32: =SUMPRODUCT($W$6:$AC$6,W32:AC32) -> 0 | AE32: =VLOOKUP(C32,#REF!,1,0) -> #REF!
C33: 509H6 | D33: MACHALI SEWEL | E33: MACHALÍ SEWEL | F33: - | G33: CIERRE DEFINITIVO | H33: TNM | J33: PINERUA JAIMES JESUS | L33: MACHALÍ | M33: BERNARDO OHIGGINS | O33: 509H6 | P33: 12HRS | Q33: NO | S33: 0 | T33: NO | U33: NO | AD33: =SUMPRODUCT($W$6:$AC$6,W33:AC33) -> 0 | AE33: =VLOOKUP(C33,#REF!,1,0) -> #REF!
C34: 50AFU | D34: SANTA AMALIA | E34: SANTA AMALIA | F34: - | G34: CIERRE DEFINITIVO | H34: TNM | J34: ARAYA BURGOS ARIEL | L34: LA FLORIDA | M34: METROPOLITANA | O34: 50AFU | P34: 12HRS | Q34: NO | S34: 0 | T34: NO | U34: NO | AD34: =SUMPRODUCT($W$6:$AC$6,W34:AC34) -> 0 | AE34: =VLOOKUP(C34,#REF!,1,0) -> #REF!
C35: 50AGU | D35: EL AGUILUCHO | E35: EL AGUILUCHO | F35: - | G35: CIERRE DEFINITIVO | H35: TNM | J35: ARAYA BURGOS ARIEL | L35: PROVIDENCIA | M35: METROPOLITANA | O35: 50AGU | P35: 12HRS | Q35: NO | S35: 0 | T35: NO | U35: NO | AD35: =SUMPRODUCT($W$6:$AC$6,W35:AC35) -> 0 | AE35: =VLOOKUP(C35,#REF!,1,0) -> #REF!
C36: 50AJL | D36: LA CASTELLANA | E36: LA CASTELLANA | F36: - | G36: CIERRE DEFINITIVO | H36: T2024 | J36: LOPEZ CALDERON LUIS GERARDO | L36: LAS CONDES | M36: METROPOLITANA | O36: 50AJL | P36: 12HRS | Q36: NO | S36: 0 | T36: NO | U36: NO | AD36: =SUMPRODUCT($W$6:$AC$6,W36:AC36) -> 0 | AE36: =VLOOKUP(C36,#REF!,1,0) -> #REF!
C37: 50AL4 | D37: ANIBAL PINTO | E37: ANIBAL PINTO | F37: - | G37: CIERRE DEFINITIVO | H37: T2024 | J37: ZAMBRANO JARA CAROLINA GRACIELA | L37: CONCEPCIÓN | M37: BIOBIO | O37: 50AL4 | P37: 12HRS | Q37: NO | S37: 0 | T37: NO | U37: NO | AD37: =SUMPRODUCT($W$6:$AC$6,W37:AC37) -> 0 | AE37: =VLOOKUP(C37,#REF!,1,0) -> #REF!
C38: 50AZF | D38: PUDAHUEL SAN PABLO 2 | E38: PUDAHUEL SAN PABLO 2 | F38: - | G38: CIERRE DEFINITIVO | H38: TNM | J38: 0 | L38: PUDAHUEL | M38: METROPOLITANA | O38: 50AZF | P38: 12HRS | Q38: NO | S38: 0 | T38: NO | U38: NO | AD38: =SUMPRODUCT($W$6:$AC$6,W38:AC38) -> 0 | AE38: =VLOOKUP(C38,#REF!,1,0) -> #REF!
C39: 50BER | D39: EL BERGANTIN | E39: EL BERGANTIN | F39: - | G39: CIERRE DEFINITIVO | H39: TMCB | J39: LIAZ MONTERO GABRIEL | L39: LAS CONDES | M39: METROPOLITANA | O39: 50BER | P39: 12HRS | Q39: NO | S39: 0 | T39: NO | U39: NO | AD39: =SUMPRODUCT($W$6:$AC$6,W39:AC39) -> 0 | AE39: =VLOOKUP(C39,#REF!,1,0) -> #REF!
C40: 50BLL | D40: BILBAO LOS LEONES | E40: BILBAO LOS LEONES | F40: - | G40: CIERRE DEFINITIVO | H40: TMCB | J40: RODRIGUEZ ABREU ROSA | L40: PROVIDENCIA | M40: METROPOLITANA | O40: 50BLL | P40: 12HRS | Q40: NO | S40: 0 | T40: NO | U40: NO | AD40: =SUMPRODUCT($W$6:$AC$6,W40:AC40) -> 0 | AE40: =VLOOKUP(C40,#REF!,1,0) -> #REF!
C41: 50BMP | D41: SANTO DOMINGO | E41: SANTO DOMINGO | F41: - | G41: CIERRE DEFINITIVO | H41: TNM | J41: BENITEZ QUILODRAN HUGO | L41: SANTIAGO | M41: METROPOLITANA | O41: 50BMP | P41: 12HRS | Q41: NO | S41: 0 | T41: NO | U41: NO | AD41: =SUMPRODUCT($W$6:$AC$6,W41:AC41) -> 0 | AE41: =VLOOKUP(C41,#REF!,1,0) -> #REF!
C42: 50CEI | D42: BARCELONA | E42: BARCELONA | F42: - | G42: CIERRE DEFINITIVO | H42: T2024 | J42: ARAYA BURGOS ARIEL | L42: LA FLORIDA | M42: METROPOLITANA | O42: 50CEI | P42: 12HRS | Q42: NO | S42: 0 | T42: NO | U42: NO | AD42: =SUMPRODUCT($W$6:$AC$6,W42:AC42) -> 0 | AE42: =VLOOKUP(C42,#REF!,1,0) -> #REF!
C43: 50DBW | D43: RENACA 1 | E43: REÑACA 1 | F43: - | G43: CIERRE DEFINITIVO | H43: TNM | J43: ESCOBAR VALDES VALESKA SOLEDAD | L43: VIÑA DEL MAR | M43: VALPARAISO | O43: 50DBW | P43: 12HRS | Q43: NO | S43: 0 | T43: NO | U43: NO | AD43: =SUMPRODUCT($W$6:$AC$6,W43:AC43) -> 0 | AE43: =VLOOKUP(C43,#REF!,1,0) -> #REF!
C44: 50DXJ | D44: PROVIDENCIA 1 | E44: PROVIDENCIA 1 | F44: - | G44: CIERRE DEFINITIVO | H44: TMCB | J44: 0 | L44: PROVIDENCIA | M44: METROPOLITANA | O44: 50DXJ | P44: 12HRS | Q44: NO | S44: 0 | T44: NO | U44: NO | AD44: =SUMPRODUCT($W$6:$AC$6,W44:AC44) -> 0 | AE44: =VLOOKUP(C44,#REF!,1,0) -> #REF!
C45: 50EVA | D45: PRAT SALINAS | E45: PRAT SALINAS | F45: - | G45: CIERRE DEFINITIVO | H45: TNM | J45: MENDOZA GIL BREYNER JOSE | L45: SAN FELIPE | M45: VALPARAISO | O45: 50EVA | P45: 12HRS | Q45: NO | S45: 0 | T45: NO | U45: NO | AD45: =SUMPRODUCT($W$6:$AC$6,W45:AC45) -> 0 | AE45: =VLOOKUP(C45,#REF!,1,0) -> #REF!
...

Sheet FEB_26
D1: 1 | E1: lider | F1: 1 | G1: =F1*D1 -> 1
D2: 1 | E2: jefe sala | F2: 1 | G2: =F2*D2 -> 1
D3: 4 | E3: pt 25 | F3: 0.56 | G3: =F3*D3 -> 2.24
D4: 4 | E4: pt 15 | F4: 0.34 | G4: =F4*D4 -> 1.36
G5: =SUM(G1:G4) -> 5.6
C6: 1 | D6: =C6+1 -> 2 | E6: =D6+1 -> 3 | F6: =E6+1 -> 4 | G6: 5 | H6: =G6+1 -> 6 | I6: =H6+1 -> 7 | J6: =I6+1 -> 8 | K6: =J6+1 -> 9 | L6: =K6+1 -> 10 | M6: =L6+1 -> 11 | N6: =M6+1 -> 12 | O6: =N6+1 -> 13 | ... T6: =S6+1 -> 18 | U6: 20 | W6: 1 | X6: 1 | Y6: 1 | Z6: =30/44 -> 0.68181818 | AA6: =25/44 -> 0.56818182 | AB6: =20/44 -> 0.45454545 | AC6: =15/44 -> 0.34090909
C7: CECO | D7: NOMBRE MAESTRA | E7: GEO | F7: FTE AUT | G7: ESTADO RH | H7: GENERACION | I7: JEFE OPERACIONES | J7: ASESOR TIENDA | K7: TIENDA ESTIVAL | L7: COMUNA | M7: REGION | N7: RECLUTADOR | O7: CECO | P7: JORNADA OPERACIÓN | Q7: PLAN RESCATE | R7: OBJETIVO VENTA | S7: MACROZONA | T7: TIENDA BATTING | U7: ONE TIME | V7: OBSERVACION | W7: LIDER | X7: JEFE DE SALA | Y7: CAJERO | Z7: CAJERO PT 30 | AA7: PT25 | AB7: CAJERP PT 20 | AC7: PT15
C8: 50GBU | D8: FRANCISCO DE AGUIRRE | E8: FRANCISCO DE AGUIRRE | F8: 11.68 | G8: Abierta | H8: TMCB | I8: CLAUDIO MONTES | J8: MENDOZA GIL BREYNER JOSE | K8: NO | L8: VITACURA | M8: METROPOLITANA | N8: PALOMARES MAIKEL | O8: 50GBU | P8: 24HRS | Q8: NO | S8: VITACURA - NORTE | T8: NO | U8: NO | W8: 1 | X8: 2 | Y8: 8 | Z8: 1 | AD8: =SUMPRODUCT($W$6:$AC$6,W8:AC8) -> 11.681818
C9: 50JMU | D9: LYON 1 | E9: LYON 1 | F9: 12 | G9: Abierta | H9: TMCB | I9: CLAUDIO MONTES | J9: BARRIOS BAPTISTA JUAN JOSE | K9: NO | L9: PROVIDENCIA | M9: METROPOLITANA | N9: NAVARRO CAREAGA JOSE | O9: 50JMU | P9: 24HRS | Q9: NO | S9: PROVIDENCIA | T9: NO | U9: NO | W9: 1 | X9: 2 | Y9: 9 | AD9: =SUMPRODUCT($W$6:$AC$6,W9:AC9) -> 12
C10: 50OSP | D10: SAN PASCUAL | E10: OKM SAN PASCUAL | F10: 11.68 | G10: Abierta | H10: TMCB | I10: CLAUDIO MONTES | J10: GAMERRE URZUA CECILIA | K10: NO | L10: LAS CONDES | M10: METROPOLITANA | N10: PALOMARES MAIKEL | O10: 50OSP | P10: 24HRS | Q10: NO | S10: EJE APOQUINDO | T10: NO | U10: NO | W10: 1 | X10: 2 | Y10: 8 | Z10: 1 | AD10: =SUMPRODUCT($W$6:$AC$6,W10:AC10) -> 11.681818
C11: 50OLI | D11: LIBERTAD 2 | E11: OKM VIÑA DEL MAR | F11: 10 | G11: Abierta | H11: TMCB | I11: ANTONIA MACCHIAVELLO | J11: ESCOBAR VALDES VALESKA SOLEDAD | K11: SI | L11: VIÑA DEL MAR | M11: VALPARAISO | N11: NAVARRO CAREAGA JOSE | O11: 50OLI | P11: 24HRS | Q11: NO | S11: REGIONES - COSTA NORTE | T11: NO | U11: NO | W11: 1 | X11: 2 | Y11: 7 | AD11: =SUMPRODUCT($W$6:$AC$6,W11:AC11) -> 10
C12: 50RBP | D12: LIMACHE VIANA | E12: LIMACHE VIANA | F12: 9 | G12: Abierta | H12: TMCB | I12: ANTONIA MACCHIAVELLO | J12: ESCOBAR VALDES VALESKA SOLEDAD | K12: SI | L12: VIÑA DEL MAR | M12: VALPARAISO | N12: NAVARRO CAREAGA JOSE | O12: 50RBP | P12: 24HRS | Q12: NO | S12: REGIONES - COSTA SUR | T12: NO | U12: NO | W12: 1 | X12: 2 | Y12: 6 | AD12: =SUMPRODUCT($W$6:$AC$6,W12:AC12) -> 9
C13: 50JIO | D13: APOQUINDO 7 | E13: APOQUINDO 7 | F13: 8.45 | G13: Abierta | H13: TMCB | I13: CLAUDIO MONTES | J13: GAMERRE URZUA CECILIA | K13: NO | L13: LAS CONDES | M13: METROPOLITANA | N13: PALOMARES MAIKEL | O13: 50JIO | P13: 24HRS | Q13: NO | S13: EJE APOQUINDO | T13: NO | U13: NO | W13: 1 | X13: 2 | Y13: 5 | AB13: 1 | AD13: =SUMPRODUCT($W$6:$AC$6,W13:AC13) -> 8.4545455
C14: 50OMQ | D14: MANQUEHUE | E14: OKM MANQUEHUE SUR | F14: 10.58 | G14: Abierta | H14: TMCB | I14: CLAUDIO MONTES | J14: BENITEZ QUILODRAN HUGO | K14: NO | L14: LAS CONDES | M14: METROPOLITANA | N14: GOMEZ FLORES JAVIERA | O14: 50OMQ | P14: 24HRS | Q14: NO | S14: LAS CONDES - PROVIDENCIA SUR | T14: NO | U14: NO | W14: 1 | X14: 2 | Y14: 7 | AA14: 1 | AD14: =SUMPRODUCT($W$6:$AC$6,W14:AC14) -> 10.568182
C15: 50OMS | D15: MANUEL DE LA LASTRA | E15: OKM MANUEL DE LA LASTRA | F15: 10.24 | G15: Abierta | H15: TMCB | I15: CLAUDIO MONTES | J15: BENITEZ QUILODRAN HUGO | K15: NO | L15: LA REINA | M15: METROPOLITANA | N15: GOMEZ FLORES JAVIERA | O15: 50OMS | P15: 24HRS | Q15: NO | S15: LAS CONDES - PROVIDENCIA SUR | T15: NO | U15: NO | W15: 1 | X15: 2 | Y15: 6 | Z15: 1 | AA15: 1 | AD15: =SUMPRODUCT($W$6:$AC$6,W15:AC15) -> 10.25
C16: 506J4 | D16: PORTUGAL | E16: PORTUGAL | F16: 8.68 | G16: Abierta | H16: TNM | I16: ANTONIA MACCHIAVELLO | J16: LIAZ MONTERO GABRIEL | K16: NO | L16: SANTIAGO | M16: METROPOLITANA | N16: NAVARRO CAREAGA JOSE | O16: 506J4 | P16: 24HRS | Q16: NO | S16: SANTIAGO CENTRO | T16: NO | U16: NO | W16: 1 | X16: 2 | Y16: 5 | Z16: 1 | AD16: =SUMPRODUCT($W$6:$AC$6,W16:AC16) -> 8.6818182
C17: 50OEY | D17: ELIODORO YANEZ 2 | E17: ELIODORO YAÑEZ 2 | F17: 8.9 | G17: Abierta | H17: TMCB | I17: CLAUDIO MONTES | J17: LOPEZ MEZA LUIS JOSÉ | K17: NO | L17: PROVIDENCIA | M17: METROPOLITANA | N17: PALOMARES MAIKEL | O17: 50OEY | P17: 24HRS | Q17: NO | S17: EJE PROVIDENCIA | T17: NO | U17: NO | W17: 1 | X17: 2 | Y17: 5 | AB17: 2 | AD17: =SUMPRODUCT($W$6:$AC$6,W17:AC17) -> 8.9090909
C18: 50RNT | D18: ROSARIO NORTE | E18: ROSARIO NORTE | F18: 8 | G18: Abierta | H18: TMCB | I18: CLAUDIO MONTES | J18: GAMERRE URZUA CECILIA | K18: NO | L18: LAS CONDES | M18: METROPOLITANA | N18: PALOMARES MAIKEL | O18: 50RNT | P18: 12HRS | Q18: NO | S18: EJE APOQUINDO | T18: NO | U18: NO | W18: 1 | X18: 1 | Y18: 6 | AD18: =SUMPRODUCT($W$6:$AC$6,W18:AC18) -> 8
C19: 506RS | D19: METRO LA CISTERNA | E19: METRO LA CISTERNA | F19: 5 | G19: Abierta | H19: TNM | I19: ANTONIA MACCHIAVELLO | J19: RODRIGUEZ ABREU ROSA | K19: NO | L19: LA CISTERNA | M19: METROPOLITANA | N19: QUINTANA VICUÑA SANTIAGO | O19: 506RS | P19: 12HRS | Q19: NO | S19: METRO | T19: SI | U19: NO | W19: 1 | X19: 1 | Y19: 3 | AD19: =SUMPRODUCT($W$6:$AC$6,W19:AC19) -> 5
C20: 50FF5 | D20: METRO GRUTA LOURDES | E20: Metro Gruta de Lourdes | F20: 5 | G20: Abierta | H20: TNM | I20: ANTONIA MACCHIAVELLO | J20: RODRIGUEZ ABREU ROSA | K20: NO | L20: QUINTA NORMAL | M20: METROPOLITANA | N20: QUINTANA VICUÑA SANTIAGO | O20: 50FF5 | P20: 12HRS | Q20: NO | S20: METRO | T20: SI | U20: NO | W20: 1 | X20: 1 | Y20: 3 | AD20: =SUMPRODUCT($W$6:$AC$6,W20:AC20) -> 5
C21: 50KJP | D21: METRO HOSPITAL EL PINO | E21: METRO HOSPITAL PINO | F21: 5 | G21: Abierta | H21: TNM | I21: ANTONIA MACCHIAVELLO | J21: RODRIGUEZ ABREU ROSA | K21: NO | L21: SAN BERNARDO | M21: METROPOLITANA | N21: QUINTANA VICUÑA SANTIAGO | O21: 50KJP | P21: 12HRS | Q21: NO | S21: METRO | T21: SI | U21: NO | W21: 1 | X21: 1 | Y21: 3 | AD21: =SUMPRODUCT($W$6:$AC$6,W21:AC21) -> 5
C22: 50OPI | D22: PLAZA ITALIA | E22: OKM PLAZA ITALIA | F22: 8.45 | G22: Abierta | H22: TMCB | I22: CLAUDIO MONTES | J22: LOPEZ MEZA LUIS JOSÉ | K22: NO | L22: PROVIDENCIA | M22: METROPOLITANA | N22: PALOMARES MAIKEL | O22: 50OPI | P22: 12HRS | Q22: NO | S22: EJE PROVIDENCIA | T22: NO | U22: NO | W22: 1 | X22: 1 | Y22: 6 | AB22: 1 | AD22: =SUMPRODUCT($W$6:$AC$6,W22:AC22) -> 8.4545455
C23: 50KOA | D23: LUIS PASTEUR | E23: LUIS PASTEUR | F23: 8 | G23: Abierta | H23: TMCB | I23: CLAUDIO MONTES | J23: MENDOZA GIL BREYNER JOSE | K23: NO | L23: VITACURA | M23: METROPOLITANA | N23: PALOMARES MAIKEL | O23: 50KOA | P23: 24HRS | Q23: NO | S23: VITACURA - NORTE | T23: NO | U23: NO | W23: 1 | X23: 2 | Y23: 5 | AD23: =SUMPRODUCT($W$6:$AC$6,W23:AC23) -> 8
C24: 50HCL | D24: ALCANTARA 2 | E24: ALCANTARA 2 | F24: 7 | G24: Abierta | H24: TMCB | I24: CLAUDIO MONTES | J24: GAMERRE URZUA CECILIA | K24: NO | L24: LAS CONDES | M24: METROPOLITANA | N24: PALOMARES MAIKEL | O24: 50HCL | P24: 12HRS | Q24: NO | S24: EJE APOQUINDO | T24: NO | U24: NO | W24: 1 | X24: 1 | Y24: 5 | AD24: =SUMPRODUCT($W$6:$AC$6,W24:AC24) -> 7
C25: 50OAM | D25: OKM MALL ARAUCO MAIPU | E25: OKM MALL ARAUCO MAIPU | F25: 5.79 | G25: Abierta | H25: TMCB | I25: ANTONIA MACCHIAVELLO | J25: PINERUA JAIMES JESUS | K25: NO | L25: MAIPÚ | M25: METROPOLITANA | N25: GOMEZ FLORES JAVIERA | O25: 50OAM | P25: 12HRS | Q25: NO | S25: SANTIAGO SURPONIENTE | T25: NO | U25: NO | W25: 1 | X25: 2 | Y25: 2 | AB25: 1 | AC25: 1 | AD25: =SUMPRODUCT($W$6:$AC$6,W25:AC25) -> 5.7954545
C26: 50OJJ | D26: BADAJOZ | E26: BADAJOZ CLP | F26: 6.68 | G26: Abierta | H26: TMCB | I26: CLAUDIO MONTES | J26: GAMERRE URZUA CECILIA | K26: NO | L26: LAS CONDES | M26: METROPOLITANA | N26: PALOMARES MAIKEL | O26: 50OJJ | P26: 12HRS | Q26: NO | S26: EJE APOQUINDO | T26: NO | U26: NO | W26: 1 | X26: 1 | Y26: 4 | Z26: 1 | AD26: =SUMPRODUCT($W$6:$AC$6,W26:AC26) -> 6.6818182
C27: 50VKK | D27: ALCANTARA 1 | E27: ALCANTARA 1 | F27: 7.68 | G27: Abierta | H27: TMCB | I27: CLAUDIO MONTES | J27: BENITEZ QUILODRAN HUGO | K27: NO | L27: LAS CONDES | M27: METROPOLITANA | N27: GOMEZ FLORES JAVIERA | O27: 50VKK | P27: 12HRS | Q27: NO | S27: LAS CONDES - PROVIDENCIA SUR | T27: NO | U27: NO | W27: 1 | X27: 1 | Y27: 5 | Z27: 1 | AD27: =SUMPRODUCT($W$6:$AC$6,W27:AC27) -> 7.6818182
C28: 50OMC | D28: MACUL | E28: OKM MACUL | F28: 10.36 | G28: Abierta | H28: TMCB | I28: ANTONIA MACCHIAVELLO | J28: PINERUA JAIMES JESUS | K28: NO | L28: MACUL | M28: METROPOLITANA | N28: GOMEZ FLORES JAVIERA | O28: 50OMC | P28: 24HRS | Q28: NO | S28: SANTIAGO SURPONIENTE | T28: NO | U28: NO | W28: 1 | X28: 2 | Y28: 6 | Z28: 2 | AD28: =SUMPRODUCT($W$6:$AC$6,W28:AC28) -> 10.363636
C29: 50NRA | D29: APOQUINDO 2 | E29: APOQUINDO 2 | F29: 7 | G29: Abierta | H29: TMCB | I29: CLAUDIO MONTES | J29: GAMERRE URZUA CECILIA | K29: NO | L29: LAS CONDES | M29: METROPOLITANA | N29: PALOMARES MAIKEL | O29: 50NRA | P29: 12HRS | Q29: NO | S29: EJE APOQUINDO | T29: NO | U29: NO | W29: 1 | X29: 1 | Y29: 5 | AD29: =SUMPRODUCT($W$6:$AC$6,W29:AC29) -> 7
C30: 50EDF | D30: EJERCITO ALAMEDA | E30: EJERCITO ALAMEDA | F30: 7 | G30: Abierta | H30: TMCB | I30: ANTONIA MACCHIAVELLO | J30: LIAZ MONTERO GABRIEL | K30: SI | L30: SANTIAGO | M30: METROPOLITANA | N30: NAVARRO CAREAGA JOSE | O30: 50EDF | P30: 12HRS | Q30: NO | S30: SANTIAGO CENTRO | T30: NO | U30: NO | W30: 1 | X30: 1 | Y30: 5 | AD30: =SUMPRODUCT($W$6:$AC$6,W30:AC30) -> 7
C31: 50OLS | D31: LUIS CARRERA | E31: LUIS CARRERA | F31: 7 | G31: Abierta | H31: TMCB | I31: CLAUDIO MONTES | J31: MENDOZA GIL BREYNER JOSE | K31: NO | L31: VITACURA | M31: METROPOLITANA | N31: PALOMARES MAIKEL | O31: 50OLS | P31: 12HRS | Q31: NO | S31: VITACURA - NORTE | T31: NO | U31: NO | W31: 1 | X31: 1 | Y31: 5 | AD31: =SUMPRODUCT($W$6:$AC$6,W31:AC31) -> 7
C32: 50UMT | D32: LYON 3 | E32: LYON 3 | F32: 7 | G32: Abierta | H32: TMCB | I32: CLAUDIO MONTES | J32: BARRIOS BAPTISTA JUAN JOSE | K32: NO | L32: PROVIDENCIA | M32: METROPOLITANA | N32: NAVARRO CAREAGA JOSE | O32: 50UMT | P32: 12HRS | Q32: NO | S32: PROVIDENCIA | T32: NO | U32: NO | W32: 1 | X32: 1 | Y32: 5 | AD32: =SUMPRODUCT($W$6:$AC$6,W32:AC32) -> 7
C33: 50ONC | D33: NATANIEL COX 2 | E33: NATANIEL COX 2 | F33: 7 | G33: Abierta | H33: TMCB | I33: ANTONIA MACCHIAVELLO | J33: LIAZ MONTERO GABRIEL | K33: NO | L33: SANTIAGO | M33: METROPOLITANA | N33: NAVARRO CAREAGA JOSE | O33: 50ONC | P33: 12HRS | Q33: NO | S33: SANTIAGO CENTRO | T33: NO | U33: NO | W33: 1 | X33: 1 | Y33: 5 | AD33: =SUMPRODUCT($W$6:$AC$6,W33:AC33) -> 7
C34: 50OAL | D34: ALAMEDA 1 | E34: OKM ALAMEDA | F34: 7 | G34: Abierta | H34: TMCB | I34: ANTONIA MACCHIAVELLO | J34: LIAZ MONTERO GABRIEL | K34: NO | L34: SANTIAGO | M34: METROPOLITANA | N34: NAVARRO CAREAGA JOSE | O34: 50OAL | P34: 12HRS | Q34: NO | S34: SANTIAGO CENTRO | T34: NO | U34: ONE TIME | W34: 1 | X34: 2 | Y34: 4 | AD34: =SUMPRODUCT($W$6:$AC$6,W34:AC34) -> 7
C35: 50MAD | D35: METRO BIO BIO | E35: METRO BIOBIO | F35: 5 | G35: Abierta | H35: TMCB | I35: ANTONIA MACCHIAVELLO | J35: RODRIGUEZ ABREU ROSA | K35: NO | L35: SAN MIGUEL | M35: METROPOLITANA | N35: QUINTANA VICUÑA SANTIAGO | O35: 50MAD | P35: 12HRS | Q35: NO | S35: METRO | T35: NO | U35: NO | W35: 1 | X35: 1 | Y35: 3 | AD35: =SUMPRODUCT($W$6:$AC$6,W35:AC35) -> 5
C36: 50ARD | D36: NUNOA | E36: ÑUÑOA | F36: 6 | G36: Abierta | H36: TMCB | I36: ANTONIA MACCHIAVELLO | J36: RUIZ FERRER VANNA | K36: NO | L36: ÑUÑOA | M36: METROPOLITANA | N36: QUINTANA VICUÑA SANTIAGO | O36: 50ARD | P36: 12HRS | Q36: NO | S36: EJE IRARRAZAVAL | T36: NO | U36: NO | W36: 1 | X36: 1 | Y36: 4 | AD36: =SUMPRODUCT($W$6:$AC$6,W36:AC36) -> 6
C37: 50ARE | D37: COLON 1 | E37: COLON 1 | F37: 6 | G37: Abierta | H37: TMCB | I37: CLAUDIO MONTES | J37: BENITEZ QUILODRAN HUGO | K37: NO | L37: LAS CONDES | M37: METROPOLITANA | N37: GOMEZ FLORES JAVIERA | O37: 50ARE | P37: 12HRS | Q37: NO | S37: LAS CONDES - PROVIDENCIA SUR | T37: NO | U37: NO | W37: 1 | X37: 1 | Y37: 4 | AD37: =SUMPRODUCT($W$6:$AC$6,W37:AC37) -> 6
C38: 50CPN | D38: CARLOS PENA | E38: CARLOS PEÑA | F38: 6 | G38: Abierta | H38: TMCB | I38: CLAUDIO MONTES | J38: ARAYA BURGOS ARIEL | K38: NO | L38: LAS CONDES | M38: METROPOLITANA | N38: GOMEZ FLORES JAVIERA | O38: 50CPN | P38: 12HRS | Q38: NO | S38: SANTIAGO ORIENTE | T38: NO | U38: NO | W38: 1 | X38: 1 | Y38: 4 | AD38: =SUMPRODUCT($W$6:$AC$6,W38:AC38) -> 6
C39: 50HSP | D39: HOSPITALES | E39: HOSPITALES | F39: 6 | G39: Abierta | H39: TMCB | I39: ANTONIA MACCHIAVELLO | J39: PINERUA JAIMES JESUS | K39: NO | L39: INDEPENDENCIA | M39: METROPOLITANA | N39: GOMEZ FLORES JAVIERA | O39: 50HSP | P39: 12HRS | Q39: NO | S39: SANTIAGO SURPONIENTE | T39: NO | U39: NO | W39: 1 | X39: 1 | Y39: 4 | AD39: =SUMPRODUCT($W$6:$AC$6,W39:AC39) -> 6
C40: 50NMT | D40: EL GOLF | E40: EL GOLF | F40: 5 | G40: Abierta | H40: TMCB | I40: CLAUDIO MONTES | J40: GAMERRE URZUA CECILIA | K40: NO | L40: LAS CONDES | M40: METROPOLITANA | N40: PALOMARES MAIKEL | O40: 50NMT | P40: 12HRS | Q40: NO | S40: EJE APOQUINDO | T40: NO | U40: NO | W40: 1 | X40: 1 | Y40: 3 | AD40: =SUMPRODUCT($W$6:$AC$6,W40:AC40) -> 5
...

Sheet Hoja2
A1: CECO | B1: NOMBRE MAESTRA
A2: 50GBU | B2: FRANCISCO DE AGUIRRE
A3: 50JMU | B3: LYON 1
A4: 50OSP | B4: SAN PASCUAL
A5: 50OLI | B5: LIBERTAD 2
A6: 50RBP | B6: LIMACHE VIANA
A7: 50JIO | B7: APOQUINDO 7
A8: 50OMQ | B8: MANQUEHUE
A9: 50OMS | B9: MANUEL DE LA LASTRA
A10: 506J4 | B10: PORTUGAL
A11: 50OEY | B11: ELIODORO YANEZ 2
A12: 50BRI | B12: LAS BRISAS
... A17: 50AQC | B17: VON SCHROEDER

Sheet Hoja1
B3: CECO | C3: NOMBRE MAESTRA | D3: FTE AUT | E3: LIDER | F3: JEFE DE SALA | G3: CAJERO | H3: CAJERP PT 20 | I3: CAJERO PT 30 | J3: CAJERO PT 25 | K3: CAJERO PT 15
B4: 50GBU | C4: FRANCISCO DE AGUIRRE | D4: 11.68 | E4: =HLOOKUP(D4,'COMPOSICION FTE'!$C$3:$AL$11,2,0) -> #N/A
B5: 50JMU | C5: LYON 1 | D5: 12
B6: 50OSP | C6: SAN PASCUAL | D6: 11.68
B7: 50OLI | C7: LIBERTAD 2 | D7: 10
B8: 50RBP | C8: LIMACHE VIANA | D8: 9
B9: 50JIO | C9: APOQUINDO 7 | D9: 8.45
B10: 50OMQ | C10: MANQUEHUE | D10: 10.58
B11: 50OMS | C11: MANUEL DE LA LASTRA | D11: 10.24
B12: 506J4 | C12: PORTUGAL | D12: 8.68
B13: 50OEY | C13: ELIODORO YANEZ 2 | D13: 8.9
B14: 50RNT | C14: ROSARIO NORTE | D14: 8
B15: 50DKO | C15: METRO FRANKLIN | D15: 7
B16: 50DSH | C16: METRO NUNOA | D16: 7.45
... B37: 50OCH | C37: CACHAGUA | D37: 5
B38: 50OEM | C38: OKM CIUDAD EMPRESARIAL | D38: -
B39: 50OIR | C39: OKM IRARRAZAVAL | D39: 6
B40: 50OPD | C40: PROVIDENCIA - CONDELL | D40: 5
B41: 50OQU | C41: QUINTA | D41: 6
B42: 50OZA | C42: ZAPALLAR | D42: 5
B43: 50SLM | C43: APOQUINDO 4 | D43: 6
B44: 50VLX | C44: APOQUINDO 1 | D44: 6
B45: 50VOP | C45: SAN DAMIAN | D45: 8.34
B46: 5033F | C46: VITACURA RIESCO | D46: 5.56
B47: 50BJT | C47: HUECHURABA | D47: 10.13
B48: 50BPT | C48: ECUADOR PURISIMA | D48: -
B49: 50BRI | C49: LAS BRISAS | D49: 10
B50: 50CLC | C50: CLINICA LAS CONDES | D50: 6
B51: 50CQD | C51: MARCHANT PEREIRA | D51: 6
B52: 50HEN | C52: HENDAYA | D52: 5
B53: 50HIS | C53: PLAZA SOTOMAYOR VALPARAISO | D53: 9
B54: 50NBN | C54: BILBAO MONTT | D54: 5
B55: 50OCT | C55: NORUEGA | D55: 6
B56: 50OPH | C56: GUARDIA VIEJA | D56: 5
B57: 50XUH | C57: MATTE PEREZ | D57: 6
B58: 508R8 | C58: METRO TOBALABA | D58: 6.16
B59: 50EFO | C59: ENRIQUE FOSTER | D59: 5
B60: 50MPC | C60: METRO CAL Y CANTO | D60: 6
... B68: 50OCR | C68: CHESTERTON 2 | D68: 6.58
B69: 50ODA | C69: OKM DIEGO DE ALMAGRO | D69: -
...

Sheet ENERO_26
D1: 1 | E1: lider | F1: 1 | G1: =F1*D1 -> 1
D2: 1 | E2: jefe sala | F2: 1 | G2: =F2*D2 -> 1
D3: 4 | E3: pt 25 | F3: 0.56 | G3: =F3*D3 -> 2.24
D4: 4 | E4: pt 15 | F4: 0.34 | G4: =F4*D4 -> 1.36
G5: =SUM(G1:G4) -> 5.6
C6: 1 | D6: =C6+1 -> 2 | E6: =D6+1 -> 3 | F6: =E6+1 -> 4 | G6: 5 | H6: =G6+1 -> 6 | I6: =H6+1 -> 7 | J6: =I6+1 -> 8 | K6: =J6+1 -> 9 | L6: =K6+1 -> 10 | M6: =L6+1 -> 11 | N6: =M6+1 -> 12 | O6: =N6+1 -> 13 | ... T6: =S6+1 -> 18 | U6: 20
C7: CECO | D7: NOMBRE MAESTRA | E7: GEO | F7: FTE AUT | G7: ESTADO RH | H7: GENERACION | I7: JEFE OPERACIONES | J7: ASESOR TIENDA | K7: TIENDA ESTIVAL | L7: COMUNA | M7: REGION | N7: RECLUTADOR | O7: CECO | P7: JORNADA OPERACIÓN | Q7: PLAN RESCATE | R7: OBJETIVO VENTA | S7: MACROZONA | T7: TIENDA BATTING | U7: ONE TIME | V7: OBSERVACION
C8: 50GBU | D8: FRANCISCO DE AGUIRRE | E8: FRANCISCO DE AGUIRRE | F8: 11.68 | G8: Abierta | H8: TMCB | J8: MENDOZA GIL BREYNER JOSE | K8: NO | L8: VITACURA | M8: METROPOLITANA | N8: PALOMARES MAIKEL | O8: 50GBU | P8: 24HRS | Q8: NO | S8: VITACURA - NORTE | T8: NO | U8: NO
C9: 50JMU | D9: LYON 1 | E9: LYON 1 | F9: 12 | G9: Abierta | H9: TMCB | J9: BARRIOS BAPTISTA JUAN JOSE | K9: NO | L9: PROVIDENCIA | M9: METROPOLITANA | N9: JOSE NAVARRO CAREAGA | O9: 50JMU | P9: 24HRS | Q9: NO | S9: PROVIDENCIA | T9: NO | U9: NO
C10: 50OSP | D10: SAN PASCUAL | E10: OKM SAN PASCUAL | F10: 11.68 | G10: Abierta | H10: TMCB | J10: GAMERRE URZUA CECILIA | K10: NO | L10: LAS CONDES | M10: METROPOLITANA | N10: PALOMARES MAIKEL | O10: 50OSP | P10: 24HRS | Q10: NO | S10: EJE APOQUINDO | T10: NO | U10: NO
C11: 50OLI | D11: OKM LIBERTAD | E11: OKM VIÑA DEL MAR | F11: 10 | G11: Abierta | H11: TMCB | J11: ESCOBAR VALDES VALESKA SOLEDAD | K11: SI | L11: VIÑA DEL MAR | M11: VALPARAISO | N11: JOSE NAVARRO CAREAGA | O11: 50OLI | P11: 24HRS | Q11: NO | S11: REGIONES - COSTA NORTE | T11: NO | U11: NO
C12: 50RBP | D12: LIMACHE VIANA | E12: LIMACHE VIANA | F12: 9 | G12: Abierta | H12: TMCB | J12: ESCOBAR VALDES VALESKA SOLEDAD | K12: SI | L12: VIÑA DEL MAR | M12: VALPARAISO | N12: JOSE NAVARRO CAREAGA | O12: 50RBP | P12: 24HRS | Q12: NO | S12: REGIONES - COSTA SUR | T12: NO | U12: NO
C13: 50JIO | D13: APOQUINDO 7 | E13: APOQUINDO 7 | F13: 8.45 | G13: Abierta | H13: TMCB | J13: GAMERRE URZUA CECILIA | K13: NO | L13: LAS CONDES | M13: METROPOLITANA | N13: PALOMARES MAIKEL | O13: 50JIO | P13: 24HRS | Q13: NO | S13: EJE APOQUINDO | T13: NO | U13: NO
C14: 50OMQ | D14: MANQUEHUE | E14: OKM MANQUEHUE SUR | F14: =10.58 -> 10.58 | G14: Abierta | H14: TMCB | J14: BENITEZ QUILODRAN HUGO | K14: NO | L14: LAS CONDES | M14: METROPOLITANA | N14: GOMEZ FLORES JAVIERA | O14: 50OMQ | P14: 24HRS | Q14: NO | S14: LAS CONDES - PROVIDENCIA SUR | T14: NO | U14: NO
C15: 50OMS | D15: MANUEL DE LA LASTRA | E15: OKM MANUEL DE LA LASTRA | F15: =11.68-1-1+0.56 -> 10.24 | G15: Abierta | H15: TMCB | J15: BENITEZ QUILODRAN HUGO | K15: NO | L15: LA REINA | M15: METROPOLITANA | N15: GOMEZ FLORES JAVIERA | O15: 50OMS | P15: 24HRS | Q15: NO | S15: LAS CONDES - PROVIDENCIA SUR | T15: NO | U15: NO
C16: 506J4 | D16: PORTUGAL | E16: PORTUGAL | F16: 8.68 | G16: Abierta | H16: TNM | J16: LIAZ MONTERO GABRIEL | K16: NO | L16: SANTIAGO | M16: METROPOLITANA | N16: JOSE NAVARRO CAREAGA | O16: 506J4 | P16: 24HRS | Q16: NO | S16: SANTIAGO CENTRO | T16: NO | U16: NO
C17: 50OEY | D17: ELIODORO YANEZ 2 | E17: ELIODORO YAÑEZ 2 | F17: 8.9 | G17: Abierta | H17: TMCB | J17: LOPEZ MEZA LUIS JOSÉ | K17: NO | L17: PROVIDENCIA | M17: METROPOLITANA | N17: PALOMARES MAIKEL | O17: 50OEY | P17: 24HRS | Q17: NO | S17: EJE PROVIDENCIA | T17: NO | U17: NO
C18: 50RNT | D18: ROSARIO NORTE | E18: ROSARIO NORTE | F18: 8 | G18: Abierta | H18: TMCB | J18: GAMERRE URZUA CECILIA | K18: NO | L18: LAS CONDES | M18: METROPOLITANA | N18: PALOMARES MAIKEL | O18: 50RNT | P18: 12HRS | Q18: NO | S18: EJE APOQUINDO | T18: NO | U18: NO
C19: 50DKO | D19: METRO FRANKLIN | E19: METRO FRANKLIN | F19: 7 | G19: Abierta | H19: TMCB | J19: RODRIGUEZ ABREU ROSA | K19: NO | L19: SANTIAGO | M19: METROPOLITANA | N19: QUINTANA VICUÑA SANTIAGO | O19: 50DKO | P19: 12HRS | Q19: NO | S19: METRO | T19: NO | U19: NO
C20: 50DSH | D20: METRO NUNOA | E20: METRO ÑUÑOA | F20: 7.45 | G20: Abierta | H20: TMCB | J20: RODRIGUEZ ABREU ROSA | K20: NO | L20: ÑUÑOA | M20: METROPOLITANA | N20: QUINTANA VICUÑA SANTIAGO | O20: 50DSH | P20: 12HRS | Q20: NO | S20: METRO | T20: NO | U20: NO
C21: 50GJS | D21: METRO LOS LEONES | E21: METRO LOS LEONES | F21: 6.16 | G21: Abierta | H21: TMCB | J21: RODRIGUEZ ABREU ROSA | K21: NO | L21: PROVIDENCIA | M21: METROPOLITANA | N21: QUINTANA VICUÑA SANTIAGO | O21: 50GJS | P21: 12HRS | Q21: NO | S21: METRO | T21: NO | U21: NO
C22: 50OPI | D22: PLAZA ITALIA | E22: OKM PLAZA ITALIA | F22: 8.45 | G22: Abierta | H22: TMCB | J22: LOPEZ MEZA LUIS JOSÉ | K22: NO | L22: PROVIDENCIA | M22: METROPOLITANA | N22: PALOMARES MAIKEL | O22: 50OPI | P22: 12HRS | Q22: NO | S22: EJE PROVIDENCIA | T22: NO | U22: NO
C23: 50KOA | D23: LUIS PASTEUR | E23: LUIS PASTEUR | F23: 7 | G23: Abierta | H23: TMCB | J23: MENDOZA GIL BREYNER JOSE | K23: NO | L23: VITACURA | M23: METROPOLITANA | N23: PALOMARES MAIKEL | O23: 50KOA | P23: 12HRS | Q23: NO | S23: VITACURA - NORTE | T23: NO | U23: NO
C24: 50NRA | D24: APOQUINDO 2 | E24: APOQUINDO 2 | F24: 7 | G24: Abierta | H24: TMCB | J24: GAMERRE URZUA CECILIA | K24: NO | L24: LAS CONDES | M24: METROPOLITANA | N24: PALOMARES MAIKEL | O24: 50NRA | P24: 12HRS | Q24: NO | S24: EJE APOQUINDO | T24: NO | U24: NO
C25: 50OAM | D25: OKM MALL ARAUCO MAIPU | E25: OKM MALL ARAUCO MAIPU K166 CAJAS | F25: =5.45+0.34 -> 5.79 | G25: Abierta | H25: TMCB | J25: PINERUA JAIMES JESUS | K25: NO | L25: MAIPÚ | M25: METROPOLITANA | N25: GOMEZ FLORES JAVIERA | O25: 50OAM | P25: 12HRS | Q25: NO | S25: SANTIAGO SURPONIENTE | T25: NO | U25: NO
C26: 50OJJ | D26: BADAJOZ | E26: BADAJOZ CLP | F26: 6.68 | G26: CIERRE TEMPORAL | H26: TMCB | J26: GAMERRE URZUA CECILIA | K26: NO | L26: LAS CONDES | M26: METROPOLITANA | N26: PALOMARES MAIKEL | O26: 50OJJ | P26: 12HRS | Q26: NO | S26: EJE APOQUINDO | T26: NO | U26: NO
C27: 50VKK | D27: ALCANTARA 1 | E27: ALCANTARA 1 | F27: 7 | G27: Abierta | H27: TMCB | J27: BENITEZ QUILODRAN HUGO | K27: NO | L27: LAS CONDES | M27: METROPOLITANA | N27: GOMEZ FLORES JAVIERA | O27: 50VKK | P27: 12HRS | Q27: NO | S27: LAS CONDES - PROVIDENCIA SUR | T27: NO | U27: NO
C28: 50OMC | D28: MACUL | E28: OKM MACUL | F28: 8.68 | G28: Abierta | H28: TMCB | J28: PINERUA JAIMES JESUS | K28: NO | L28: MACUL | M28: METROPOLITANA | N28: GOMEZ FLORES JAVIERA | O28: 50OMC | P28: 12HRS | Q28: NO | S28: SANTIAGO SURPONIENTE | T28: NO | U28: NO
C29: 50UMT | D29: LYON 3 | E29: LYON 3 | F29: 7 | G29: Abierta | H29: TMCB | J29: BARRIOS BAPTISTA JUAN JOSE | K29: NO | L29: PROVIDENCIA | M29: METROPOLITANA | N29: JOSE NAVARRO CAREAGA | O29: 50UMT | P29: 12HRS | Q29: NO | S29: PROVIDENCIA | T29: NO | U29: NO
C30: 50EDF | D30: EJERCITO ALAMEDA | E30: EJERCITO ALAMEDA | F30: 7 | G30: Abierta | H30: TMCB | J30: LIAZ MONTERO GABRIEL | K30: SI | L30: SANTIAGO | M30: METROPOLITANA | N30: JOSE NAVARRO CAREAGA | O30: 50EDF | P30: 12HRS | Q30: NO | S30: SANTIAGO CENTRO | T30: NO | U30: NO
C31: 50HCL | D31: ALCANTARA 2 | E31: ALCANTARA 2 | F31: 7 | G31: Abierta | H31: TMCB | J31: GAMERRE URZUA CECILIA | K31: NO | L31: LAS CONDES | M31: METROPOLITANA | N31: PALOMARES MAIKEL | O31: 50HCL | P31: 12HRS | Q31: NO | S31: EJE APOQUINDO | T31: NO | U31: NO
C32: 50OLS | D32: LUIS CARRERA | E32: LUIS CARRERA | F32: 7 | G32: Abierta | H32: TMCB | J32: MENDOZA GIL BREYNER JOSE | K32: NO | L32: VITACURA | M32: METROPOLITANA | N32: PALOMARES MAIKEL | O32: 50OLS | P32: 12HRS | Q32: NO | S32: VITACURA - NORTE | T32: NO | U32: NO
C33: 50OTP | D33: TOBALABA 1 | E33: OKM TOBALABA | F33: 7 | G33: Abierta | H33: TMCB | J33: MONTT FUENTES JAIME IGNACIO | K33: NO | L33: LAS CONDES | M33: METROPOLITANA | N33: QUINTANA VICUÑA SANTIAGO | O33: 50OTP | P33: 12HRS | Q33: NO | S33: LAS CONDES NORTE | T33: NO | U33: NO
C34: 50OAL | D34: ALAMEDA 1 | E34: OKM ALAMEDA | F34: 7 | G34: Abierta | H34: TMCB | J34: LIAZ MONTERO GABRIEL | K34: NO | L34: SANTIAGO | M34: METROPOLITANA | N34: JOSE NAVARRO CAREAGA | O34: 50OAL | P34: 12HRS | Q34: NO | S34: SANTIAGO CENTRO | T34: NO | U34: ONE TIME
C35: 50UCH | D35: METRO U DE CHILE | E35: METRO U DE CHILE | F35: 6.68 | G35: CIERRE TEMPORAL | H35: TMCB | J35: RODRIGUEZ ABREU ROSA | L35: SANTIAGO | M35: METROPOLITANA | N35: QUINTANA VICUÑA SANTIAGO | O35: 50UCH | P35: 12HRS | Q35: NO | S35: METRO | T35: NO | U35: NO
C36: 50ARD | D36: NUNOA | E36: ÑUÑOA | F36: 6 | G36: Abierta | H36: TMCB | J36: RUIZ FERRER VANNA | K36: NO | L36: ÑUÑOA | M36: METROPOLITANA | N36: QUINTANA VICUÑA SANTIAGO | O36: 50ARD | P36: 12HRS | Q36: NO | S36: EJE IRARRAZAVAL | T36: NO | U36: NO
C37: 50ARE | D37: COLON 1 | E37: COLON 1 | F37: 6 | G37: Abierta | H37: TMCB | J37: BENITEZ QUILODRAN HUGO | K37: NO | L37: LAS CONDES | M37: METROPOLITANA | N37: GOMEZ FLORES JAVIERA | O37: 50ARE | P37: 12HRS | Q37: NO | S37: LAS CONDES - PROVIDENCIA SUR | T37: NO | U37: NO
C38: 50CPN | D38: CARLOS PENA | E38: CARLOS PEÑA | F38: 6 | G38: Abierta | H38: TMCB | J38: ARAYA BURGOS ARIEL | K38: NO | L38: LAS CONDES | M38: METROPOLITANA | N38: GOMEZ FLORES JAVIERA | O38: 50CPN | P38: 12HRS | Q38: NO | S38: SANTIAGO ORIENTE | T38: NO | U38: NO
C39: 50HSP | D39: HOSPITALES | E39: HOSPITALES | F39: 6 | G39: Abierta | H39: TMCB | J39: PINERUA JAIMES JESUS | K39: NO | L39: INDEPENDENCIA | M39: METROPOLITANA | N39: GOMEZ FLORES JAVIERA | O39: 50HSP | P39: 12HRS | Q39: NO | S39: SANTIAGO SURPONIENTE | T39: NO | U39: NO
C40: 50NMT | D40: EL GOLF | E40: EL GOLF | F40: 5 | G40: Abierta | H40: TMCB | J40: GAMERRE URZUA CECILIA | K40: NO | L40: LAS CONDES | M40: METROPOLITANA | N40: PALOMARES MAIKEL | O40: 50NMT | P40: 12HRS | Q40: NO | S40: EJE APOQUINDO | T40: NO | U40: NO
...

Sheet DICIEMBRE_25
D2: =15/44 -> 0.34090909 | E2: 10.58 | F2: 9.45 | G2: =E2-F2 -> 1.13
C6: 1 | D6: =C6+1 -> 2 | E6: =D6+1 -> 3 | F6: =E6+1 -> 4 | G6: =F6+1 -> 5 | H6: =G6+1 -> 6 | I6: =H6+1 -> 7 | J6: =I6+1 -> 8 | K6: =J6+1 -> 9 | ... T6: =S6+1 -> 18 | U6: 20
C7: CECO | D7: NOMBRE MAESTRA | E7: GEO | F7: FTE AUT | G7: ESTADO RH | H7: GENERACION | I7: JEFE OPERACIONES | J7: ASESOR TIENDA | K7: TIENDA ESTIVAL | L7: COMUNA | M7: REGION | N7: RECLUTADOR | O7: CECO | P7: JORNADA OPERACIÓN | Q7: PLAN RESCATE | R7: OBJETIVO VENTA | S7: MACROZONA | T7: TIENDA BATTING | U7: ONE TIME | V7: OBSERVACION
C8: 50GBU | D8: FRANCISCO DE AGUIRRE | E8: FRANCISCO DE AGUIRRE | F8: 11.68 | G8: Abierta | H8: TMCB | I8: BRESCIA RIVERA RODRIGO | J8: MENDOZA GIL BREYNER JOSE | K8: NO | L8: VITACURA | M8: METROPOLITANA | N8: PALOMARES MAIKEL | O8: 50GBU | P8: 24HRS | Q8: NO | S8: VITACURA - NORTE | T8: NO
C9: 50JMU | D9: LYON 1 | E9: LYON 1 | F9: 12 | G9: Abierta | H9: TMCB | I9: BRESCIA RIVERA RODRIGO | J9: BARRIOS BAPTISTA JUAN JOSE | K9: NO | L9: PROVIDENCIA | M9: METROPOLITANA | N9: JOSE NAVARRO CAREAGA | O9: 50JMU | P9: 24HRS | Q9: NO | S9: PROVIDENCIA | T9: NO
C10: 50OSP | D10: SAN PASCUAL | E10: OKM SAN PASCUAL | F10: 11.68 | G10: Abierta | H10: TMCB | I10: SESA DIEGO MIGUEL | J10: GAMERRE URZUA CECILIA | K10: NO | L10: LAS CONDES | M10: METROPOLITANA | N10: PALOMARES MAIKEL | O10: 50OSP | P10: 24HRS | Q10: NO | S10: EJE APOQUINDO | T10: NO
C11: 50OLI | D11: OKM LIBERTAD | E11: OKM VIÑA DEL MAR | F11: 10 | G11: Abierta | H11: TMCB | I11: SESA DIEGO MIGUEL | J11: ESCOBAR VALDES VALESKA SOLEDAD | K11: SI | L11: VIÑA DEL MAR | M11: VALPARAISO | N11: JOSE NAVARRO CAREAGA | O11: 50OLI | P11: 24HRS | Q11: NO | S11: REGIONES - COSTA NORTE | T11: NO
C12: 50RBP | D12: LIMACHE VIANA | E12: LIMACHE VIANA | F12: 9 | G12: Abierta | H12: TMCB | I12: SESA DIEGO MIGUEL | J12: ESCOBAR VALDES VALESKA SOLEDAD | K12: SI | L12: VIÑA DEL MAR | M12: VALPARAISO | N12: JOSE NAVARRO CAREAGA | O12: 50RBP | P12: 24HRS | Q12: NO | S12: REGIONES - COSTA SUR | T12: NO
C13: 50JIO | D13: APOQUINDO 7 | E13: APOQUINDO 7 | F13: 8.45 | G13: Abierta | H13: TMCB | I13: SESA DIEGO MIGUEL | J13: GAMERRE URZUA CECILIA | K13: NO | L13: LAS CONDES | M13: METROPOLITANA | N13: PALOMARES MAIKEL | O13: 50JIO | P13: 24HRS | Q13: NO | S13: EJE APOQUINDO | T13: NO
C14: 50OMQ | D14: MANQUEHUE | E14: OKM MANQUEHUE SUR | F14: =10.58 -> 10.58 | G14: Abierta | H14: TMCB | I14: BRESCIA RIVERA RODRIGO | J14: BENITEZ QUILODRAN HUGO | K14: NO | L14: LAS CONDES | M14: METROPOLITANA | N14: GOMEZ FLORES JAVIERA | O14: 50OMQ | P14: 24HRS | Q14: NO | S14: LAS CONDES - PROVIDENCIA SUR | T14: NO
C15: 50OMS | D15: MANUEL DE LA LASTRA | E15: OKM MANUEL DE LA LASTRA | F15: 10.13 | G15: Abierta | H15: TMCB | I15: BRESCIA RIVERA RODRIGO | J15: BENITEZ QUILODRAN HUGO | K15: NO | L15: LA REINA | M15: METROPOLITANA | N15: GOMEZ FLORES JAVIERA | O15: 50OMS | P15: 24HRS | Q15: NO | S15: LAS CONDES - PROVIDENCIA SUR | T15: NO
C16: 506J4 | D16: PORTUGAL | E16: PORTUGAL | F16: 8.68 | G16: Abierta | H16: TNM | I16: BRESCIA RIVERA RODRIGO | J16: LIAZ MONTERO GABRIEL | K16: NO | L16: SANTIAGO | M16: METROPOLITANA | N16: JOSE NAVARRO CAREAGA | O16: 506J4 | P16: 24HRS | Q16: NO | S16: SANTIAGO CENTRO | T16: NO
C17: 50OEY | D17: ELIODORO YANEZ 2 | E17: ELIODORO YAÑEZ 2 | F17: 8.9 | G17: Abierta | H17: TMCB | I17: BRESCIA RIVERA RODRIGO | J17: LOPEZ MEZA LUIS JOSÉ | K17: NO | L17: PROVIDENCIA | M17: METROPOLITANA | N17: PALOMARES MAIKEL | O17: 50OEY | P17: 24HRS | Q17: NO | S17: EJE PROVIDENCIA | T17: NO
C18: 50RNT | D18: ROSARIO NORTE | E18: ROSARIO NORTE | F18: 8 | G18: Abierta | H18: TMCB | I18: SESA DIEGO MIGUEL | J18: GAMERRE URZUA CECILIA | K18: NO | L18: LAS CONDES | M18: METROPOLITANA | N18: PALOMARES MAIKEL | O18: 50RNT | P18: 12HRS | Q18: NO | S18: EJE APOQUINDO | T18: NO
C19: 50DKO | D19: METRO FRANKLIN | E19: METRO FRANKLIN | F19: 7 | G19: Abierta | H19: TMCB | I19: BRESCIA RIVERA RODRIGO | J19: RODRIGUEZ ABREU ROSA | K19: NO | L19: SANTIAGO | M19: METROPOLITANA | N19: QUINTANA VICUÑA SANTIAGO | O19: 50DKO | P19: 12HRS | Q19: NO | S19: METRO | T19: NO
C20: 50DSH | D20: METRO NUNOA | E20: METRO ÑUÑOA | F20: 7.45 | G20: Abierta | H20: TMCB | I20: BRESCIA RIVERA RODRIGO | J20: RODRIGUEZ ABREU ROSA | K20: NO | L20: ÑUÑOA | M20: METROPOLITANA | N20: QUINTANA VICUÑA SANTIAGO | O20: 50DSH | P20: 12HRS | Q20: NO | S20: METRO | T20: NO
C21: 50GJS | D21: METRO LOS LEONES | E21: METRO LOS LEONES | F21: 6.16 | G21: Abierta | H21: TMCB | I21: BRESCIA RIVERA RODRIGO | J21: RODRIGUEZ ABREU ROSA | K21: NO | L21: PROVIDENCIA | M21: METROPOLITANA | N21: QUINTANA VICUÑA SANTIAGO | O21: 50GJS | P21: 12HRS | Q21: NO | S21: METRO | T21: NO | U21: ONE TIME
